2021-09-03 09:56:26,538	Exception occurred:
<type 'exceptions.RuntimeError'>: All connection attempts failed for localhost, use {phantom.connection_test: false} to disable it
  File "/usr/local/lib/python2.7/dist-packages/yandextank/core/consoleworker.py", line 375, in run
    self.core.plugins_configure()

  File "/usr/local/lib/python2.7/dist-packages/yandextank/core/tankcore.py", line 245, in plugins_configure
    plugin.configure()

  File "/usr/local/lib/python2.7/dist-packages/yandextank/plugins/Phantom/plugin.py", line 72, in configure
    self.phantom_config = self.phantom.config_file

  File "/usr/local/lib/python2.7/dist-packages/yandextank/plugins/Phantom/plugin.py", line 81, in phantom
    self._phantom.read_config()

  File "/usr/local/lib/python2.7/dist-packages/yandextank/plugins/Phantom/utils.py", line 95, in read_config
    stream.read_config()

  File "/usr/local/lib/python2.7/dist-packages/yandextank/plugins/Phantom/utils.py", line 275, in read_config
    self.address, do_test_connect, explicit_port)

  File "/usr/local/lib/python2.7/dist-packages/yandextank/common/util.py", line 555, in resolve
    raise RuntimeError(msg % address_str)

2021-09-03 09:56:26,544	Job number is not available yet
2021-09-03 09:56:26,545	Job number is not available yet
2021-09-03 09:56:26,551	File already exists: /var/loadtest/logs/2021-09-03_09-56-26.431447/answ_wNEDa2.log
2021-09-03 09:56:26,553	File already exists: /var/loadtest/logs/2021-09-03_09-56-26.431447/phantom_stat_80dEH1.log
2021-09-03 09:56:26,554	File already exists: /var/loadtest/logs/2021-09-03_09-56-26.431447/phantom_Tvpxkp.log
2021-09-03 09:56:26,556	File already exists: /var/loadtest/logs/2021-09-03_09-56-26.431447/phout_9i1xVO.log
2021-09-03 09:56:26,559	File not found to collect: validation_error.yaml
2021-09-03 09:56:56,411	Failed to install monitoring agent to 192.168.1.74
Traceback (most recent call last):
  File "/usr/local/lib/python2.7/dist-packages/yandextank/plugins/Telegraf/client.py", line 209, in install
    out, errors, err_code = self.ssh.execute(cmd)
  File "/usr/local/lib/python2.7/dist-packages/yandextank/common/util.py", line 72, in execute
    with self.connect() as client:
  File "/usr/local/lib/python2.7/dist-packages/yandextank/common/util.py", line 42, in connect
    timeout=self.timeout, )
  File "/usr/local/lib/python2.7/dist-packages/paramiko/client.py", line 362, in connect
    raise NoValidConnectionsError(errors)
NoValidConnectionsError: [Errno None] Unable to connect to port 22 on 192.168.1.74
2021-09-03 09:57:45,680	Interrupting
2021-09-03 09:57:47,707	Job number is not available yet
2021-09-03 09:57:47,709	Job number is not available yet
2021-09-03 09:57:47,716	File already exists: /var/loadtest/logs/2021-09-03_09-56-53.445097/answ_zg3x8H.log
2021-09-03 09:57:47,719	File already exists: /var/loadtest/logs/2021-09-03_09-56-53.445097/phantom_CIMijr.conf
2021-09-03 09:57:47,722	File already exists: /var/loadtest/logs/2021-09-03_09-56-53.445097/phantom_stdout_stderr_ZpKuR1.log
2021-09-03 09:57:47,726	File not found to collect: validation_error.yaml
2021-09-03 09:57:47,729	File already exists: /var/loadtest/logs/2021-09-03_09-56-53.445097/phantom_stat_qPrh2B.log
2021-09-03 09:57:47,731	File already exists: /var/loadtest/logs/2021-09-03_09-56-53.445097/phout_p8ExAq.log
2021-09-03 09:57:47,735	File already exists: /var/loadtest/logs/2021-09-03_09-56-53.445097/phantom_wwZgDH.log
2021-09-03 09:57:47,738	File already exists: /var/loadtest/logs/2021-09-03_09-56-53.445097/monitoring_NmxC_M.xml
2021-09-03 10:05:43,831	Failed to install monitoring agent to 192.168.1.74
Traceback (most recent call last):
  File "/usr/local/lib/python2.7/dist-packages/yandextank/plugins/Telegraf/client.py", line 209, in install
    out, errors, err_code = self.ssh.execute(cmd)
  File "/usr/local/lib/python2.7/dist-packages/yandextank/common/util.py", line 72, in execute
    with self.connect() as client:
  File "/usr/local/lib/python2.7/dist-packages/yandextank/common/util.py", line 42, in connect
    timeout=self.timeout, )
  File "/usr/local/lib/python2.7/dist-packages/paramiko/client.py", line 362, in connect
    raise NoValidConnectionsError(errors)
NoValidConnectionsError: [Errno None] Unable to connect to port 22 on 192.168.1.74
2021-09-03 10:07:48,990	Interrupting
2021-09-03 10:07:50,469	Job number is not available yet
2021-09-03 10:07:50,471	Job number is not available yet
2021-09-03 10:07:50,486	File already exists: /var/loadtest/logs/2021-09-03_10-05-43.428837/phantom_stat_RjtbrT.log
2021-09-03 10:07:50,489	File already exists: /var/loadtest/logs/2021-09-03_10-05-43.428837/phantom_xn3ywu.conf
2021-09-03 10:07:50,493	File already exists: /var/loadtest/logs/2021-09-03_10-05-43.428837/monitoring_lZaT5r.xml
2021-09-03 10:07:50,499	File already exists: /var/loadtest/logs/2021-09-03_10-05-43.428837/phout_oGt3o3.log
2021-09-03 10:07:50,504	File already exists: /var/loadtest/logs/2021-09-03_10-05-43.428837/answ_SjX9xh.log
2021-09-03 10:07:50,509	File not found to collect: validation_error.yaml
2021-09-03 10:07:50,514	File already exists: /var/loadtest/logs/2021-09-03_10-05-43.428837/phantom_stdout_stderr_579rrZ.log
2021-09-03 10:07:50,518	File already exists: /var/loadtest/logs/2021-09-03_10-05-43.428837/phantom_h0HpaE.log
