2021-09-12 09:54:45,084	Failed to install monitoring agent to 192.168.1.74
Traceback (most recent call last):
  File "/usr/local/lib/python2.7/dist-packages/yandextank/plugins/Telegraf/client.py", line 209, in install
    out, errors, err_code = self.ssh.execute(cmd)
  File "/usr/local/lib/python2.7/dist-packages/yandextank/common/util.py", line 72, in execute
    with self.connect() as client:
  File "/usr/local/lib/python2.7/dist-packages/yandextank/common/util.py", line 42, in connect
    timeout=self.timeout, )
  File "/usr/local/lib/python2.7/dist-packages/paramiko/client.py", line 362, in connect
    raise NoValidConnectionsError(errors)
NoValidConnectionsError: [Errno None] Unable to connect to port 22 on 192.168.1.74
2021-09-12 09:55:34,110	Autostop criterion requested test stop: http(5xx,100%,30s)
2021-09-12 09:55:34,122	Autostop criterion requested test stop: 5xx codes count higher than 100.0% for 30s, since 1631440501
2021-09-12 09:55:35,845	Job number is not available yet
2021-09-12 09:55:35,846	Job number is not available yet
2021-09-12 09:55:35,853	File already exists: /var/loadtest/logs/2021-09-12_09-54-42.908298/answ_oNNNtt.log
2021-09-12 09:55:35,856	File already exists: /var/loadtest/logs/2021-09-12_09-54-42.908298/phantom_stdout_stderr_krgqdv.log
2021-09-12 09:55:35,860	File already exists: /var/loadtest/logs/2021-09-12_09-54-42.908298/phantom_7S6oLK.log
2021-09-12 09:55:35,864	File already exists: /var/loadtest/logs/2021-09-12_09-54-42.908298/autostop_report.txt
2021-09-12 09:55:35,867	File already exists: /var/loadtest/logs/2021-09-12_09-54-42.908298/phout_N_tIc1.log
2021-09-12 09:55:35,869	File already exists: /var/loadtest/logs/2021-09-12_09-54-42.908298/phantom_hPCJ0V.conf
2021-09-12 09:55:35,873	File not found to collect: validation_error.yaml
2021-09-12 09:55:35,877	File already exists: /var/loadtest/logs/2021-09-12_09-54-42.908298/phantom_stat_a7miPc.log
2021-09-12 09:55:35,880	File already exists: /var/loadtest/logs/2021-09-12_09-54-42.908298/monitoring_tfG0BZ.xml
2021-09-12 10:01:11,017	Failed to install monitoring agent to 192.168.1.74
Traceback (most recent call last):
  File "/usr/local/lib/python2.7/dist-packages/yandextank/plugins/Telegraf/client.py", line 209, in install
    out, errors, err_code = self.ssh.execute(cmd)
  File "/usr/local/lib/python2.7/dist-packages/yandextank/common/util.py", line 72, in execute
    with self.connect() as client:
  File "/usr/local/lib/python2.7/dist-packages/yandextank/common/util.py", line 42, in connect
    timeout=self.timeout, )
  File "/usr/local/lib/python2.7/dist-packages/paramiko/client.py", line 362, in connect
    raise NoValidConnectionsError(errors)
NoValidConnectionsError: [Errno None] Unable to connect to port 22 on 192.168.1.74
2021-09-12 10:01:19,672	Interrupting
2021-09-12 10:01:26,406	Job number is not available yet
2021-09-12 10:01:26,408	Job number is not available yet
2021-09-12 10:01:26,416	File already exists: /var/loadtest/logs/2021-09-12_10-01-10.561105/phout_joLrB6.log
2021-09-12 10:01:26,419	File already exists: /var/loadtest/logs/2021-09-12_10-01-10.561105/phantom_eJX7XH.conf
2021-09-12 10:01:26,421	File already exists: /var/loadtest/logs/2021-09-12_10-01-10.561105/answ_Fu_UIJ.log
2021-09-12 10:01:26,423	File not found to collect: validation_error.yaml
2021-09-12 10:01:26,425	File already exists: /var/loadtest/logs/2021-09-12_10-01-10.561105/phantom_KhuxRY.log
2021-09-12 10:01:26,428	File already exists: /var/loadtest/logs/2021-09-12_10-01-10.561105/monitoring_CvSVuI.xml
2021-09-12 10:01:26,431	File already exists: /var/loadtest/logs/2021-09-12_10-01-10.561105/phantom_stat_8n0AIQ.log
2021-09-12 10:01:27,265	Failed to install monitoring agent to 192.168.1.74
Traceback (most recent call last):
  File "/usr/local/lib/python2.7/dist-packages/yandextank/plugins/Telegraf/client.py", line 209, in install
    out, errors, err_code = self.ssh.execute(cmd)
  File "/usr/local/lib/python2.7/dist-packages/yandextank/common/util.py", line 72, in execute
    with self.connect() as client:
  File "/usr/local/lib/python2.7/dist-packages/yandextank/common/util.py", line 42, in connect
    timeout=self.timeout, )
  File "/usr/local/lib/python2.7/dist-packages/paramiko/client.py", line 362, in connect
    raise NoValidConnectionsError(errors)
NoValidConnectionsError: [Errno None] Unable to connect to port 22 on 192.168.1.74
2021-09-12 10:03:46,327	Job number is not available yet
2021-09-12 10:03:46,329	Job number is not available yet
2021-09-12 10:03:46,339	File already exists: /var/loadtest/logs/2021-09-12_10-01-26.857094/phantom_6P_Lx2.log
2021-09-12 10:03:46,341	File already exists: /var/loadtest/logs/2021-09-12_10-01-26.857094/monitoring_wxmF6A.xml
2021-09-12 10:03:46,344	File not found to collect: validation_error.yaml
2021-09-12 10:03:46,346	File already exists: /var/loadtest/logs/2021-09-12_10-01-26.857094/phantom_stat_C6rSHw.log
2021-09-12 10:03:46,351	File already exists: /var/loadtest/logs/2021-09-12_10-01-26.857094/answ_SjJbxy.log
2021-09-12 10:03:46,354	File already exists: /var/loadtest/logs/2021-09-12_10-01-26.857094/phantom_k7qbar.conf
2021-09-12 10:03:46,357	File already exists: /var/loadtest/logs/2021-09-12_10-01-26.857094/phout_VPb4yd.log
2021-09-12 10:03:46,358	File already exists: /var/loadtest/logs/2021-09-12_10-01-26.857094/phantom_stdout_stderr_1D9jHH.log
2021-09-16 11:54:32,220	Exception occurred:
<type 'exceptions.RuntimeError'>: All connection attempts failed for 192.168.1.74, use {phantom.connection_test: false} to disable it
  File "/usr/local/lib/python2.7/dist-packages/yandextank/core/consoleworker.py", line 375, in run
    self.core.plugins_configure()

  File "/usr/local/lib/python2.7/dist-packages/yandextank/core/tankcore.py", line 245, in plugins_configure
    plugin.configure()

  File "/usr/local/lib/python2.7/dist-packages/yandextank/plugins/Phantom/plugin.py", line 72, in configure
    self.phantom_config = self.phantom.config_file

  File "/usr/local/lib/python2.7/dist-packages/yandextank/plugins/Phantom/plugin.py", line 81, in phantom
    self._phantom.read_config()

  File "/usr/local/lib/python2.7/dist-packages/yandextank/plugins/Phantom/utils.py", line 95, in read_config
    stream.read_config()

  File "/usr/local/lib/python2.7/dist-packages/yandextank/plugins/Phantom/utils.py", line 275, in read_config
    self.address, do_test_connect, explicit_port)

  File "/usr/local/lib/python2.7/dist-packages/yandextank/common/util.py", line 555, in resolve
    raise RuntimeError(msg % address_str)

2021-09-16 11:54:32,234	Job number is not available yet
2021-09-16 11:54:32,236	Job number is not available yet
2021-09-16 11:54:32,246	File already exists: /var/loadtest/logs/2021-09-16_11-54-28.796447/phout_TFyH5R.log
2021-09-16 11:54:32,250	File already exists: /var/loadtest/logs/2021-09-16_11-54-28.796447/phantom_stat_OJbzs_.log
2021-09-16 11:54:32,253	File already exists: /var/loadtest/logs/2021-09-16_11-54-28.796447/phantom_PoF3ZO.log
2021-09-16 11:54:32,257	File not found to collect: validation_error.yaml
2021-09-16 11:54:32,259	File already exists: /var/loadtest/logs/2021-09-16_11-54-28.796447/answ_OQeurb.log
2021-09-16 11:55:34,103	Exception occurred:
<type 'exceptions.OSError'>: [Errno 2] No such file or directory: 'ammo-flat.txt'
  File "/usr/local/lib/python2.7/dist-packages/yandextank/core/consoleworker.py", line 375, in run
    self.core.plugins_configure()

  File "/usr/local/lib/python2.7/dist-packages/yandextank/core/tankcore.py", line 245, in plugins_configure
    plugin.configure()

  File "/usr/local/lib/python2.7/dist-packages/yandextank/plugins/Phantom/plugin.py", line 72, in configure
    self.phantom_config = self.phantom.config_file

  File "/usr/local/lib/python2.7/dist-packages/yandextank/plugins/Phantom/utils.py", line 106, in config_file
    self._config_file = self.compose_config()

  File "/usr/local/lib/python2.7/dist-packages/yandextank/plugins/Phantom/utils.py", line 114, in compose_config
    streams_config += stream.compose_config()

  File "/usr/local/lib/python2.7/dist-packages/yandextank/plugins/Phantom/utils.py", line 288, in compose_config
    self.stepper_wrapper.prepare_stepper()

  File "/usr/local/lib/python2.7/dist-packages/yandextank/stepper/main.py", line 212, in prepare_stepper
    self.stpd = self.__get_stpd_filename()

  File "/usr/local/lib/python2.7/dist-packages/yandextank/stepper/main.py", line 263, in __get_stpd_filename
    hashed_str += sep + opener.hash

  File "/usr/local/lib/python2.7/dist-packages/netort/resource.py", line 147, in hash
    stat = os.stat(self.f_path)

2021-09-16 11:55:34,113	Job number is not available yet
2021-09-16 11:55:34,115	Job number is not available yet
2021-09-16 11:55:34,126	File already exists: /var/loadtest/logs/2021-09-16_11-55-33.994486/phantom_stat_xXC4Uc.log
2021-09-16 11:55:34,128	File already exists: /var/loadtest/logs/2021-09-16_11-55-33.994486/phout_nlz_Jc.log
2021-09-16 11:55:34,133	File already exists: /var/loadtest/logs/2021-09-16_11-55-33.994486/phantom_Ge_Ku5.log
2021-09-16 11:55:34,136	File not found to collect: validation_error.yaml
2021-09-16 11:55:34,139	File already exists: /var/loadtest/logs/2021-09-16_11-55-33.994486/answ_roecw_.log
2021-09-16 11:55:53,903	Exception occurred:
<class 'yandextank.stepper.module_exceptions.AmmoFileError'>: Unexpected end of file: read 467 bytes instead of 900
  File "/usr/local/lib/python2.7/dist-packages/yandextank/core/consoleworker.py", line 375, in run
    self.core.plugins_configure()

  File "/usr/local/lib/python2.7/dist-packages/yandextank/core/tankcore.py", line 245, in plugins_configure
    plugin.configure()

  File "/usr/local/lib/python2.7/dist-packages/yandextank/plugins/Phantom/plugin.py", line 72, in configure
    self.phantom_config = self.phantom.config_file

  File "/usr/local/lib/python2.7/dist-packages/yandextank/plugins/Phantom/utils.py", line 106, in config_file
    self._config_file = self.compose_config()

  File "/usr/local/lib/python2.7/dist-packages/yandextank/plugins/Phantom/utils.py", line 114, in compose_config
    streams_config += stream.compose_config()

  File "/usr/local/lib/python2.7/dist-packages/yandextank/plugins/Phantom/utils.py", line 288, in compose_config
    self.stepper_wrapper.prepare_stepper()

  File "/usr/local/lib/python2.7/dist-packages/yandextank/stepper/main.py", line 228, in prepare_stepper
    self.__make_stpd_file()

  File "/usr/local/lib/python2.7/dist-packages/yandextank/stepper/main.py", line 318, in __make_stpd_file
    stepper.write(os)

  File "/usr/local/lib/python2.7/dist-packages/yandextank/stepper/main.py", line 61, in write
    for missile in self.ammo:

  File "/usr/local/lib/python2.7/dist-packages/yandextank/stepper/format.py", line 19, in <genexpr>
    "%s %s %s\n%s\n" % (len(missile), timestamp, marker, missile)

  File "/usr/local/lib/python2.7/dist-packages/yandextank/stepper/main.py", line 48, in <genexpr>
    return ((timestamp, marker or self.marker(missile), missile)

  File "/usr/local/lib/python2.7/dist-packages/yandextank/stepper/main.py", line 43, in <genexpr>
    ammo

  File "/usr/local/lib/python2.7/dist-packages/yandextank/stepper/main.py", line 44, in <genexpr>
    for ammo in ((missile, marker or self.marker(missile))

  File "/usr/local/lib/python2.7/dist-packages/yandextank/stepper/missile.py", line 139, in __iter__
    % (len(missile), chunk_size))

2021-09-16 11:55:53,915	Job number is not available yet
2021-09-16 11:55:53,917	Job number is not available yet
2021-09-16 11:55:53,929	File already exists: /var/loadtest/logs/2021-09-16_11-55-53.766055/answ_kbZeG5.log
2021-09-16 11:55:53,933	File already exists: /var/loadtest/logs/2021-09-16_11-55-53.766055/phantom_qYL8bX.log
2021-09-16 11:55:53,936	File not found to collect: validation_error.yaml
2021-09-16 11:55:53,939	File already exists: /var/loadtest/logs/2021-09-16_11-55-53.766055/phantom_stat_secN7N.log
2021-09-16 11:55:53,941	File already exists: /var/loadtest/logs/2021-09-16_11-55-53.766055/phout_mD3fiT.log
2021-09-16 11:56:15,254	Failed to install monitoring agent to 192.168.1.73
Traceback (most recent call last):
  File "/usr/local/lib/python2.7/dist-packages/yandextank/plugins/Telegraf/client.py", line 209, in install
    out, errors, err_code = self.ssh.execute(cmd)
  File "/usr/local/lib/python2.7/dist-packages/yandextank/common/util.py", line 72, in execute
    with self.connect() as client:
  File "/usr/local/lib/python2.7/dist-packages/yandextank/common/util.py", line 42, in connect
    timeout=self.timeout, )
  File "/usr/local/lib/python2.7/dist-packages/paramiko/client.py", line 362, in connect
    raise NoValidConnectionsError(errors)
NoValidConnectionsError: [Errno None] Unable to connect to port 22 on 192.168.1.73
2021-09-16 11:57:22,884	Interrupting
2021-09-16 11:57:24,707	Job number is not available yet
2021-09-16 11:57:24,708	Job number is not available yet
2021-09-16 11:57:24,720	File already exists: /var/loadtest/logs/2021-09-16_11-56-12.049166/answ_USg7O6.log
2021-09-16 11:57:24,728	File already exists: /var/loadtest/logs/2021-09-16_11-56-12.049166/phantom_ivexVi.log
2021-09-16 11:57:24,735	File already exists: /var/loadtest/logs/2021-09-16_11-56-12.049166/phantom_stdout_stderr_HOJnU7.log
2021-09-16 11:57:24,741	File already exists: /var/loadtest/logs/2021-09-16_11-56-12.049166/phout_Rf3ElZ.log
2021-09-16 11:57:24,747	File not found to collect: validation_error.yaml
2021-09-16 11:57:24,751	File already exists: /var/loadtest/logs/2021-09-16_11-56-12.049166/phantom_stat_MZg0BJ.log
2021-09-16 11:57:24,754	File already exists: /var/loadtest/logs/2021-09-16_11-56-12.049166/phantom_npv6aU.conf
2021-09-16 11:57:24,759	File already exists: /var/loadtest/logs/2021-09-16_11-56-12.049166/monitoring_RWo3Gx.xml
2021-09-16 11:58:25,974	Failed to install monitoring agent to 192.168.1.73
Traceback (most recent call last):
  File "/usr/local/lib/python2.7/dist-packages/yandextank/plugins/Telegraf/client.py", line 209, in install
    out, errors, err_code = self.ssh.execute(cmd)
  File "/usr/local/lib/python2.7/dist-packages/yandextank/common/util.py", line 72, in execute
    with self.connect() as client:
  File "/usr/local/lib/python2.7/dist-packages/yandextank/common/util.py", line 42, in connect
    timeout=self.timeout, )
  File "/usr/local/lib/python2.7/dist-packages/paramiko/client.py", line 362, in connect
    raise NoValidConnectionsError(errors)
NoValidConnectionsError: [Errno None] Unable to connect to port 22 on 192.168.1.73
2021-09-16 11:59:26,109	Autostop criterion requested test stop: net(xx,1,30)
2021-09-16 11:59:26,120	Autostop criterion requested test stop: xx net codes count higher than 1 for 30s, since 1631793532
2021-09-16 11:59:27,745	Job number is not available yet
2021-09-16 11:59:27,746	Job number is not available yet
2021-09-16 11:59:27,753	File already exists: /var/loadtest/logs/2021-09-16_11-58-25.552468/answ_hNBrWa.log
2021-09-16 11:59:27,756	File already exists: /var/loadtest/logs/2021-09-16_11-58-25.552468/monitoring_0Q9ddQ.xml
2021-09-16 11:59:27,758	File already exists: /var/loadtest/logs/2021-09-16_11-58-25.552468/phantom_stdout_stderr_clLKH2.log
2021-09-16 11:59:27,761	File already exists: /var/loadtest/logs/2021-09-16_11-58-25.552468/phout_th2fku.log
2021-09-16 11:59:27,765	File already exists: /var/loadtest/logs/2021-09-16_11-58-25.552468/autostop_report.txt
2021-09-16 11:59:27,769	File not found to collect: validation_error.yaml
2021-09-16 11:59:27,772	File already exists: /var/loadtest/logs/2021-09-16_11-58-25.552468/phantom_stat_vJtymi.log
2021-09-16 11:59:27,776	File already exists: /var/loadtest/logs/2021-09-16_11-58-25.552468/phantom_D3zoRU.log
2021-09-16 11:59:27,778	File already exists: /var/loadtest/logs/2021-09-16_11-58-25.552468/phantom_FA2N0Y.conf
2021-09-16 12:01:46,009	Exception occurred:
<class 'yandextank.stepper.module_exceptions.AmmoFileError'>: Unexpected end of file: read 447 bytes instead of 467
  File "/usr/local/lib/python2.7/dist-packages/yandextank/core/consoleworker.py", line 375, in run
    self.core.plugins_configure()

  File "/usr/local/lib/python2.7/dist-packages/yandextank/core/tankcore.py", line 245, in plugins_configure
    plugin.configure()

  File "/usr/local/lib/python2.7/dist-packages/yandextank/plugins/Phantom/plugin.py", line 72, in configure
    self.phantom_config = self.phantom.config_file

  File "/usr/local/lib/python2.7/dist-packages/yandextank/plugins/Phantom/utils.py", line 106, in config_file
    self._config_file = self.compose_config()

  File "/usr/local/lib/python2.7/dist-packages/yandextank/plugins/Phantom/utils.py", line 114, in compose_config
    streams_config += stream.compose_config()

  File "/usr/local/lib/python2.7/dist-packages/yandextank/plugins/Phantom/utils.py", line 288, in compose_config
    self.stepper_wrapper.prepare_stepper()

  File "/usr/local/lib/python2.7/dist-packages/yandextank/stepper/main.py", line 228, in prepare_stepper
    self.__make_stpd_file()

  File "/usr/local/lib/python2.7/dist-packages/yandextank/stepper/main.py", line 318, in __make_stpd_file
    stepper.write(os)

  File "/usr/local/lib/python2.7/dist-packages/yandextank/stepper/main.py", line 61, in write
    for missile in self.ammo:

  File "/usr/local/lib/python2.7/dist-packages/yandextank/stepper/format.py", line 19, in <genexpr>
    "%s %s %s\n%s\n" % (len(missile), timestamp, marker, missile)

  File "/usr/local/lib/python2.7/dist-packages/yandextank/stepper/main.py", line 48, in <genexpr>
    return ((timestamp, marker or self.marker(missile), missile)

  File "/usr/local/lib/python2.7/dist-packages/yandextank/stepper/main.py", line 43, in <genexpr>
    ammo

  File "/usr/local/lib/python2.7/dist-packages/yandextank/stepper/main.py", line 44, in <genexpr>
    for ammo in ((missile, marker or self.marker(missile))

  File "/usr/local/lib/python2.7/dist-packages/yandextank/stepper/missile.py", line 139, in __iter__
    % (len(missile), chunk_size))

2021-09-16 12:01:46,020	Job number is not available yet
2021-09-16 12:01:46,022	Job number is not available yet
2021-09-16 12:01:46,028	File already exists: /var/loadtest/logs/2021-09-16_12-01-45.877469/phout_JItg6T.log
2021-09-16 12:01:46,030	File already exists: /var/loadtest/logs/2021-09-16_12-01-45.877469/phantom_cEUGTN.log
2021-09-16 12:01:46,033	File not found to collect: validation_error.yaml
2021-09-16 12:01:46,037	File already exists: /var/loadtest/logs/2021-09-16_12-01-45.877469/phantom_stat__alUAT.log
2021-09-16 12:01:46,040	File already exists: /var/loadtest/logs/2021-09-16_12-01-45.877469/answ_w_a7nx.log
2021-09-16 12:02:11,439	Failed to install monitoring agent to 192.168.1.73
Traceback (most recent call last):
  File "/usr/local/lib/python2.7/dist-packages/yandextank/plugins/Telegraf/client.py", line 209, in install
    out, errors, err_code = self.ssh.execute(cmd)
  File "/usr/local/lib/python2.7/dist-packages/yandextank/common/util.py", line 72, in execute
    with self.connect() as client:
  File "/usr/local/lib/python2.7/dist-packages/yandextank/common/util.py", line 42, in connect
    timeout=self.timeout, )
  File "/usr/local/lib/python2.7/dist-packages/paramiko/client.py", line 362, in connect
    raise NoValidConnectionsError(errors)
NoValidConnectionsError: [Errno None] Unable to connect to port 22 on 192.168.1.73
2021-09-16 12:03:11,089	Autostop criterion requested test stop: net(xx,1,30)
2021-09-16 12:03:11,112	Autostop criterion requested test stop: xx net codes count higher than 1 for 30s, since 1631793758
2021-09-16 12:03:12,943	Job number is not available yet
2021-09-16 12:03:12,944	Job number is not available yet
2021-09-16 12:03:12,949	File already exists: /var/loadtest/logs/2021-09-16_12-02-09.306323/phout_mVINAx.log
2021-09-16 12:03:12,952	File already exists: /var/loadtest/logs/2021-09-16_12-02-09.306323/phantom_stat_tEu65I.log
2021-09-16 12:03:12,956	File already exists: /var/loadtest/logs/2021-09-16_12-02-09.306323/autostop_report.txt
2021-09-16 12:03:12,958	File already exists: /var/loadtest/logs/2021-09-16_12-02-09.306323/monitoring_FU0Lgi.xml
2021-09-16 12:03:12,960	File not found to collect: validation_error.yaml
2021-09-16 12:03:12,963	File already exists: /var/loadtest/logs/2021-09-16_12-02-09.306323/answ_ZuHeoj.log
2021-09-16 12:03:12,965	File already exists: /var/loadtest/logs/2021-09-16_12-02-09.306323/phantom_awFFDZ.log
2021-09-16 12:03:12,967	File already exists: /var/loadtest/logs/2021-09-16_12-02-09.306323/phantom_stdout_stderr_ITmTqy.log
2021-09-16 12:03:12,970	File already exists: /var/loadtest/logs/2021-09-16_12-02-09.306323/phantom_1uuISq.conf
2021-09-16 12:25:46,225	Exception occurred:
<type 'exceptions.RuntimeError'>: All connection attempts failed for 192.168.1.73, use {phantom.connection_test: false} to disable it
  File "/usr/local/lib/python2.7/dist-packages/yandextank/core/consoleworker.py", line 375, in run
    self.core.plugins_configure()

  File "/usr/local/lib/python2.7/dist-packages/yandextank/core/tankcore.py", line 245, in plugins_configure
    plugin.configure()

  File "/usr/local/lib/python2.7/dist-packages/yandextank/plugins/Phantom/plugin.py", line 72, in configure
    self.phantom_config = self.phantom.config_file

  File "/usr/local/lib/python2.7/dist-packages/yandextank/plugins/Phantom/plugin.py", line 81, in phantom
    self._phantom.read_config()

  File "/usr/local/lib/python2.7/dist-packages/yandextank/plugins/Phantom/utils.py", line 95, in read_config
    stream.read_config()

  File "/usr/local/lib/python2.7/dist-packages/yandextank/plugins/Phantom/utils.py", line 275, in read_config
    self.address, do_test_connect, explicit_port)

  File "/usr/local/lib/python2.7/dist-packages/yandextank/common/util.py", line 555, in resolve
    raise RuntimeError(msg % address_str)

2021-09-16 12:25:46,235	Job number is not available yet
2021-09-16 12:25:46,237	Job number is not available yet
2021-09-16 12:25:46,244	File already exists: /var/loadtest/logs/2021-09-16_12-25-46.111388/phantom_Hb3zSV.log
2021-09-16 12:25:46,247	File already exists: /var/loadtest/logs/2021-09-16_12-25-46.111388/phantom_stat_yi7pPb.log
2021-09-16 12:25:46,251	File already exists: /var/loadtest/logs/2021-09-16_12-25-46.111388/phout_UpBHCa.log
2021-09-16 12:25:46,256	File not found to collect: validation_error.yaml
2021-09-16 12:25:46,259	File already exists: /var/loadtest/logs/2021-09-16_12-25-46.111388/answ_lamQBR.log
2021-09-16 12:26:22,907	Exception occurred:
<class 'yandextank.stepper.module_exceptions.AmmoFileError'>: Unexpected end of file: read 467 bytes instead of 500
  File "/usr/local/lib/python2.7/dist-packages/yandextank/core/consoleworker.py", line 375, in run
    self.core.plugins_configure()

  File "/usr/local/lib/python2.7/dist-packages/yandextank/core/tankcore.py", line 245, in plugins_configure
    plugin.configure()

  File "/usr/local/lib/python2.7/dist-packages/yandextank/plugins/Phantom/plugin.py", line 72, in configure
    self.phantom_config = self.phantom.config_file

  File "/usr/local/lib/python2.7/dist-packages/yandextank/plugins/Phantom/utils.py", line 106, in config_file
    self._config_file = self.compose_config()

  File "/usr/local/lib/python2.7/dist-packages/yandextank/plugins/Phantom/utils.py", line 114, in compose_config
    streams_config += stream.compose_config()

  File "/usr/local/lib/python2.7/dist-packages/yandextank/plugins/Phantom/utils.py", line 288, in compose_config
    self.stepper_wrapper.prepare_stepper()

  File "/usr/local/lib/python2.7/dist-packages/yandextank/stepper/main.py", line 228, in prepare_stepper
    self.__make_stpd_file()

  File "/usr/local/lib/python2.7/dist-packages/yandextank/stepper/main.py", line 318, in __make_stpd_file
    stepper.write(os)

  File "/usr/local/lib/python2.7/dist-packages/yandextank/stepper/main.py", line 61, in write
    for missile in self.ammo:

  File "/usr/local/lib/python2.7/dist-packages/yandextank/stepper/format.py", line 19, in <genexpr>
    "%s %s %s\n%s\n" % (len(missile), timestamp, marker, missile)

  File "/usr/local/lib/python2.7/dist-packages/yandextank/stepper/main.py", line 48, in <genexpr>
    return ((timestamp, marker or self.marker(missile), missile)

  File "/usr/local/lib/python2.7/dist-packages/yandextank/stepper/main.py", line 43, in <genexpr>
    ammo

  File "/usr/local/lib/python2.7/dist-packages/yandextank/stepper/main.py", line 44, in <genexpr>
    for ammo in ((missile, marker or self.marker(missile))

  File "/usr/local/lib/python2.7/dist-packages/yandextank/stepper/missile.py", line 139, in __iter__
    % (len(missile), chunk_size))

2021-09-16 12:26:22,922	Job number is not available yet
2021-09-16 12:26:22,926	Job number is not available yet
2021-09-16 12:26:22,945	File already exists: /var/loadtest/logs/2021-09-16_12-26-22.775037/phout_r8NY7Z.log
2021-09-16 12:26:22,951	File already exists: /var/loadtest/logs/2021-09-16_12-26-22.775037/phantom_stat_9baDxM.log
2021-09-16 12:26:22,954	File not found to collect: validation_error.yaml
2021-09-16 12:26:22,958	File already exists: /var/loadtest/logs/2021-09-16_12-26-22.775037/phantom_omfj97.log
2021-09-16 12:26:22,961	File already exists: /var/loadtest/logs/2021-09-16_12-26-22.775037/answ_yvC4UZ.log
2021-09-16 12:26:35,273	Failed to install monitoring agent to 192.168.1.73
Traceback (most recent call last):
  File "/usr/local/lib/python2.7/dist-packages/yandextank/plugins/Telegraf/client.py", line 209, in install
    out, errors, err_code = self.ssh.execute(cmd)
  File "/usr/local/lib/python2.7/dist-packages/yandextank/common/util.py", line 72, in execute
    with self.connect() as client:
  File "/usr/local/lib/python2.7/dist-packages/yandextank/common/util.py", line 42, in connect
    timeout=self.timeout, )
  File "/usr/local/lib/python2.7/dist-packages/paramiko/client.py", line 362, in connect
    raise NoValidConnectionsError(errors)
NoValidConnectionsError: [Errno None] Unable to connect to port 22 on 192.168.1.73
2021-09-16 12:27:29,128	Failed to install monitoring agent to 192.168.1.73
Traceback (most recent call last):
  File "/usr/local/lib/python2.7/dist-packages/yandextank/plugins/Telegraf/client.py", line 209, in install
    out, errors, err_code = self.ssh.execute(cmd)
  File "/usr/local/lib/python2.7/dist-packages/yandextank/common/util.py", line 72, in execute
    with self.connect() as client:
  File "/usr/local/lib/python2.7/dist-packages/yandextank/common/util.py", line 42, in connect
    timeout=self.timeout, )
  File "/usr/local/lib/python2.7/dist-packages/paramiko/client.py", line 362, in connect
    raise NoValidConnectionsError(errors)
NoValidConnectionsError: [Errno None] Unable to connect to port 22 on 192.168.1.73
2021-09-16 12:27:56,880	Job number is not available yet
2021-09-16 12:27:56,882	Job number is not available yet
2021-09-16 12:27:56,892	File already exists: /var/loadtest/logs/2021-09-16_12-27-28.579236/phantom_iS8CeK.conf
2021-09-16 12:27:56,896	File already exists: /var/loadtest/logs/2021-09-16_12-27-28.579236/phantom_stat_I7LNbG.log
2021-09-16 12:27:56,902	File already exists: /var/loadtest/logs/2021-09-16_12-27-28.579236/monitoring_GAcFE4.xml
2021-09-16 12:27:56,911	File already exists: /var/loadtest/logs/2021-09-16_12-27-28.579236/answ_yaZ4gv.log
2021-09-16 12:27:56,915	File already exists: /var/loadtest/logs/2021-09-16_12-27-28.579236/phantom_stdout_stderr_Gut_h2.log
2021-09-16 12:27:56,920	File not found to collect: validation_error.yaml
2021-09-16 12:27:56,925	File already exists: /var/loadtest/logs/2021-09-16_12-27-28.579236/phantom_4JzA3F.log
2021-09-16 12:27:56,930	File already exists: /var/loadtest/logs/2021-09-16_12-27-28.579236/phout_W4xVDW.log
2021-09-16 12:28:23,343	Interrupting
2021-09-16 12:28:25,318	Job number is not available yet
2021-09-16 12:28:25,320	Job number is not available yet
2021-09-16 12:28:25,331	File already exists: /var/loadtest/logs/2021-09-16_12-26-33.183176/phout_QlUQEg.log
2021-09-16 12:28:25,336	File already exists: /var/loadtest/logs/2021-09-16_12-26-33.183176/monitoring_Meqnvl.xml
2021-09-16 12:28:25,344	File already exists: /var/loadtest/logs/2021-09-16_12-26-33.183176/phantom_h4gsb5.log
2021-09-16 12:28:25,348	File already exists: /var/loadtest/logs/2021-09-16_12-26-33.183176/phantom_stdout_stderr_zIwnTm.log
2021-09-16 12:28:25,353	File already exists: /var/loadtest/logs/2021-09-16_12-26-33.183176/phantom_stat_OqH6oC.log
2021-09-16 12:28:25,358	File already exists: /var/loadtest/logs/2021-09-16_12-26-33.183176/phantom_55i50C.conf
2021-09-16 12:28:25,365	File not found to collect: validation_error.yaml
2021-09-16 12:28:25,372	File already exists: /var/loadtest/logs/2021-09-16_12-26-33.183176/answ_xaOd46.log
2021-09-16 12:29:11,668	Exception occurred:
<type 'exceptions.RuntimeError'>: All connection attempts failed for 192.168.1.73, use {phantom.connection_test: false} to disable it
  File "/usr/local/lib/python2.7/dist-packages/yandextank/core/consoleworker.py", line 375, in run
    self.core.plugins_configure()

  File "/usr/local/lib/python2.7/dist-packages/yandextank/core/tankcore.py", line 245, in plugins_configure
    plugin.configure()

  File "/usr/local/lib/python2.7/dist-packages/yandextank/plugins/Phantom/plugin.py", line 72, in configure
    self.phantom_config = self.phantom.config_file

  File "/usr/local/lib/python2.7/dist-packages/yandextank/plugins/Phantom/plugin.py", line 81, in phantom
    self._phantom.read_config()

  File "/usr/local/lib/python2.7/dist-packages/yandextank/plugins/Phantom/utils.py", line 95, in read_config
    stream.read_config()

  File "/usr/local/lib/python2.7/dist-packages/yandextank/plugins/Phantom/utils.py", line 275, in read_config
    self.address, do_test_connect, explicit_port)

  File "/usr/local/lib/python2.7/dist-packages/yandextank/common/util.py", line 555, in resolve
    raise RuntimeError(msg % address_str)

2021-09-16 12:29:11,675	Job number is not available yet
2021-09-16 12:29:11,677	Job number is not available yet
2021-09-16 12:29:11,684	File already exists: /var/loadtest/logs/2021-09-16_12-29-11.562927/phantom_stat_nMKS0v.log
2021-09-16 12:29:11,686	File already exists: /var/loadtest/logs/2021-09-16_12-29-11.562927/answ_EKYkBs.log
2021-09-16 12:29:11,688	File already exists: /var/loadtest/logs/2021-09-16_12-29-11.562927/phantom_yZ2PtJ.log
2021-09-16 12:29:11,691	File not found to collect: validation_error.yaml
2021-09-16 12:29:11,694	File already exists: /var/loadtest/logs/2021-09-16_12-29-11.562927/phout_ZalxdE.log
2021-09-16 12:29:24,801	Exception occurred:
<type 'exceptions.RuntimeError'>: All connection attempts failed for 192.168.1.73, use {phantom.connection_test: false} to disable it
  File "/usr/local/lib/python2.7/dist-packages/yandextank/core/consoleworker.py", line 375, in run
    self.core.plugins_configure()

  File "/usr/local/lib/python2.7/dist-packages/yandextank/core/tankcore.py", line 245, in plugins_configure
    plugin.configure()

  File "/usr/local/lib/python2.7/dist-packages/yandextank/plugins/Phantom/plugin.py", line 72, in configure
    self.phantom_config = self.phantom.config_file

  File "/usr/local/lib/python2.7/dist-packages/yandextank/plugins/Phantom/plugin.py", line 81, in phantom
    self._phantom.read_config()

  File "/usr/local/lib/python2.7/dist-packages/yandextank/plugins/Phantom/utils.py", line 95, in read_config
    stream.read_config()

  File "/usr/local/lib/python2.7/dist-packages/yandextank/plugins/Phantom/utils.py", line 275, in read_config
    self.address, do_test_connect, explicit_port)

  File "/usr/local/lib/python2.7/dist-packages/yandextank/common/util.py", line 555, in resolve
    raise RuntimeError(msg % address_str)

2021-09-16 12:29:24,811	Job number is not available yet
2021-09-16 12:29:24,813	Job number is not available yet
2021-09-16 12:29:24,821	File already exists: /var/loadtest/logs/2021-09-16_12-29-19.713135/phout_ugLQB_.log
2021-09-16 12:29:24,824	File already exists: /var/loadtest/logs/2021-09-16_12-29-19.713135/phantom_tWkhFF.log
2021-09-16 12:29:24,826	File already exists: /var/loadtest/logs/2021-09-16_12-29-19.713135/phantom_stat__osGBt.log
2021-09-16 12:29:24,829	File not found to collect: validation_error.yaml
2021-09-16 12:29:24,833	File already exists: /var/loadtest/logs/2021-09-16_12-29-19.713135/answ_nsF84l.log
2021-09-16 12:30:20,568	Failed to install monitoring agent to 192.168.1.73
Traceback (most recent call last):
  File "/usr/local/lib/python2.7/dist-packages/yandextank/plugins/Telegraf/client.py", line 209, in install
    out, errors, err_code = self.ssh.execute(cmd)
  File "/usr/local/lib/python2.7/dist-packages/yandextank/common/util.py", line 72, in execute
    with self.connect() as client:
  File "/usr/local/lib/python2.7/dist-packages/yandextank/common/util.py", line 42, in connect
    timeout=self.timeout, )
  File "/usr/local/lib/python2.7/dist-packages/paramiko/client.py", line 362, in connect
    raise NoValidConnectionsError(errors)
NoValidConnectionsError: [Errno None] Unable to connect to port 22 on 192.168.1.73
2021-09-16 12:30:58,464	Job number is not available yet
2021-09-16 12:30:58,465	Job number is not available yet
2021-09-16 12:30:58,471	File already exists: /var/loadtest/logs/2021-09-16_12-30-20.159372/phout_E1VIEx.log
2021-09-16 12:30:58,474	File already exists: /var/loadtest/logs/2021-09-16_12-30-20.159372/phantom_bksVeh.conf
2021-09-16 12:30:58,477	File already exists: /var/loadtest/logs/2021-09-16_12-30-20.159372/phantom_eiK5C2.log
2021-09-16 12:30:58,479	File already exists: /var/loadtest/logs/2021-09-16_12-30-20.159372/monitoring_ysqhuW.xml
2021-09-16 12:30:58,482	File not found to collect: validation_error.yaml
2021-09-16 12:30:58,483	File already exists: /var/loadtest/logs/2021-09-16_12-30-20.159372/phantom_stdout_stderr_q4blxu.log
2021-09-16 12:30:58,486	File already exists: /var/loadtest/logs/2021-09-16_12-30-20.159372/phantom_stat_DzBtkJ.log
2021-09-16 12:30:58,488	File already exists: /var/loadtest/logs/2021-09-16_12-30-20.159372/answ_hAufdX.log
2021-09-16 12:31:52,477	Failed to install monitoring agent to 192.168.1.73
Traceback (most recent call last):
  File "/usr/local/lib/python2.7/dist-packages/yandextank/plugins/Telegraf/client.py", line 209, in install
    out, errors, err_code = self.ssh.execute(cmd)
  File "/usr/local/lib/python2.7/dist-packages/yandextank/common/util.py", line 72, in execute
    with self.connect() as client:
  File "/usr/local/lib/python2.7/dist-packages/yandextank/common/util.py", line 42, in connect
    timeout=self.timeout, )
  File "/usr/local/lib/python2.7/dist-packages/paramiko/client.py", line 362, in connect
    raise NoValidConnectionsError(errors)
NoValidConnectionsError: [Errno None] Unable to connect to port 22 on 192.168.1.73
2021-09-16 12:32:30,300	Job number is not available yet
2021-09-16 12:32:30,302	Job number is not available yet
2021-09-16 12:32:30,309	File already exists: /var/loadtest/logs/2021-09-16_12-31-52.071063/monitoring_GxGIRJ.xml
2021-09-16 12:32:30,312	File already exists: /var/loadtest/logs/2021-09-16_12-31-52.071063/phantom_stat_6WZUfX.log
2021-09-16 12:32:30,314	File already exists: /var/loadtest/logs/2021-09-16_12-31-52.071063/phout_hLhAkZ.log
2021-09-16 12:32:30,315	File already exists: /var/loadtest/logs/2021-09-16_12-31-52.071063/phantom_MQJHLm.conf
2021-09-16 12:32:30,318	File already exists: /var/loadtest/logs/2021-09-16_12-31-52.071063/answ_6lVTT8.log
2021-09-16 12:32:30,322	File not found to collect: validation_error.yaml
2021-09-16 12:32:30,325	File already exists: /var/loadtest/logs/2021-09-16_12-31-52.071063/phantom_stdout_stderr_fYmAzh.log
2021-09-16 12:32:30,328	File already exists: /var/loadtest/logs/2021-09-16_12-31-52.071063/phantom_rPBfeD.log
2021-09-16 12:33:12,222	Exception occurred:
<class 'yandextank.stepper.module_exceptions.AmmoFileError'>: Unexpected end of file: read 447 bytes instead of 467
  File "/usr/local/lib/python2.7/dist-packages/yandextank/core/consoleworker.py", line 375, in run
    self.core.plugins_configure()

  File "/usr/local/lib/python2.7/dist-packages/yandextank/core/tankcore.py", line 245, in plugins_configure
    plugin.configure()

  File "/usr/local/lib/python2.7/dist-packages/yandextank/plugins/Phantom/plugin.py", line 72, in configure
    self.phantom_config = self.phantom.config_file

  File "/usr/local/lib/python2.7/dist-packages/yandextank/plugins/Phantom/utils.py", line 106, in config_file
    self._config_file = self.compose_config()

  File "/usr/local/lib/python2.7/dist-packages/yandextank/plugins/Phantom/utils.py", line 114, in compose_config
    streams_config += stream.compose_config()

  File "/usr/local/lib/python2.7/dist-packages/yandextank/plugins/Phantom/utils.py", line 288, in compose_config
    self.stepper_wrapper.prepare_stepper()

  File "/usr/local/lib/python2.7/dist-packages/yandextank/stepper/main.py", line 228, in prepare_stepper
    self.__make_stpd_file()

  File "/usr/local/lib/python2.7/dist-packages/yandextank/stepper/main.py", line 318, in __make_stpd_file
    stepper.write(os)

  File "/usr/local/lib/python2.7/dist-packages/yandextank/stepper/main.py", line 61, in write
    for missile in self.ammo:

  File "/usr/local/lib/python2.7/dist-packages/yandextank/stepper/format.py", line 19, in <genexpr>
    "%s %s %s\n%s\n" % (len(missile), timestamp, marker, missile)

  File "/usr/local/lib/python2.7/dist-packages/yandextank/stepper/main.py", line 48, in <genexpr>
    return ((timestamp, marker or self.marker(missile), missile)

  File "/usr/local/lib/python2.7/dist-packages/yandextank/stepper/main.py", line 43, in <genexpr>
    ammo

  File "/usr/local/lib/python2.7/dist-packages/yandextank/stepper/main.py", line 44, in <genexpr>
    for ammo in ((missile, marker or self.marker(missile))

  File "/usr/local/lib/python2.7/dist-packages/yandextank/stepper/missile.py", line 139, in __iter__
    % (len(missile), chunk_size))

2021-09-16 12:33:12,229	Job number is not available yet
2021-09-16 12:33:12,231	Job number is not available yet
2021-09-16 12:33:12,238	File already exists: /var/loadtest/logs/2021-09-16_12-33-07.066356/answ_UTsr79.log
2021-09-16 12:33:12,240	File already exists: /var/loadtest/logs/2021-09-16_12-33-07.066356/phantom_stat_Qwa0ny.log
2021-09-16 12:33:12,243	File not found to collect: validation_error.yaml
2021-09-16 12:33:12,246	File already exists: /var/loadtest/logs/2021-09-16_12-33-07.066356/phout_hhP2Nz.log
2021-09-16 12:33:12,248	File already exists: /var/loadtest/logs/2021-09-16_12-33-07.066356/phantom_2rczPi.log
2021-09-16 12:34:12,273	Failed to install monitoring agent to 192.168.1.73
Traceback (most recent call last):
  File "/usr/local/lib/python2.7/dist-packages/yandextank/plugins/Telegraf/client.py", line 209, in install
    out, errors, err_code = self.ssh.execute(cmd)
  File "/usr/local/lib/python2.7/dist-packages/yandextank/common/util.py", line 72, in execute
    with self.connect() as client:
  File "/usr/local/lib/python2.7/dist-packages/yandextank/common/util.py", line 42, in connect
    timeout=self.timeout, )
  File "/usr/local/lib/python2.7/dist-packages/paramiko/client.py", line 362, in connect
    raise NoValidConnectionsError(errors)
NoValidConnectionsError: [Errno None] Unable to connect to port 22 on 192.168.1.73
2021-09-16 12:34:47,257	Job number is not available yet
2021-09-16 12:34:47,258	Job number is not available yet
2021-09-16 12:34:47,264	File already exists: /var/loadtest/logs/2021-09-16_12-34-11.820937/phout_xHAOoy.log
2021-09-16 12:34:47,266	File already exists: /var/loadtest/logs/2021-09-16_12-34-11.820937/phantom_UUJqJz.conf
2021-09-16 12:34:47,269	File already exists: /var/loadtest/logs/2021-09-16_12-34-11.820937/answ_6uCfR7.log
2021-09-16 12:34:47,273	File already exists: /var/loadtest/logs/2021-09-16_12-34-11.820937/phantom_stat_aMPhxF.log
2021-09-16 12:34:47,276	File already exists: /var/loadtest/logs/2021-09-16_12-34-11.820937/phantom_HZtS3m.log
2021-09-16 12:34:47,278	File already exists: /var/loadtest/logs/2021-09-16_12-34-11.820937/phantom_stdout_stderr_TGU1lb.log
2021-09-16 12:34:47,281	File not found to collect: validation_error.yaml
2021-09-16 12:34:47,283	File already exists: /var/loadtest/logs/2021-09-16_12-34-11.820937/monitoring_qGaZQH.xml
2021-09-16 12:35:30,620	Failed to install monitoring agent to 192.168.1.73
Traceback (most recent call last):
  File "/usr/local/lib/python2.7/dist-packages/yandextank/plugins/Telegraf/client.py", line 209, in install
    out, errors, err_code = self.ssh.execute(cmd)
  File "/usr/local/lib/python2.7/dist-packages/yandextank/common/util.py", line 72, in execute
    with self.connect() as client:
  File "/usr/local/lib/python2.7/dist-packages/yandextank/common/util.py", line 42, in connect
    timeout=self.timeout, )
  File "/usr/local/lib/python2.7/dist-packages/paramiko/client.py", line 362, in connect
    raise NoValidConnectionsError(errors)
NoValidConnectionsError: [Errno None] Unable to connect to port 22 on 192.168.1.73
2021-09-16 12:36:08,629	Job number is not available yet
2021-09-16 12:36:08,630	Job number is not available yet
2021-09-16 12:36:08,636	File already exists: /var/loadtest/logs/2021-09-16_12-35-30.184393/phantom_u_SGOn.log
2021-09-16 12:36:08,638	File already exists: /var/loadtest/logs/2021-09-16_12-35-30.184393/phout_ZKj2Vu.log
2021-09-16 12:36:08,640	File already exists: /var/loadtest/logs/2021-09-16_12-35-30.184393/phantom_stat_uUbZJe.log
2021-09-16 12:36:08,642	File already exists: /var/loadtest/logs/2021-09-16_12-35-30.184393/answ_P4JYY5.log
2021-09-16 12:36:08,645	File already exists: /var/loadtest/logs/2021-09-16_12-35-30.184393/phantom_stdout_stderr_EjjB82.log
2021-09-16 12:36:08,647	File not found to collect: validation_error.yaml
2021-09-16 12:36:08,649	File already exists: /var/loadtest/logs/2021-09-16_12-35-30.184393/phantom_gNsnA2.conf
2021-09-16 12:36:08,651	File already exists: /var/loadtest/logs/2021-09-16_12-35-30.184393/monitoring_lySXMe.xml
2021-09-16 12:39:26,514	Exception occurred:
<class 'yandextank.stepper.module_exceptions.AmmoFileError'>: Unexpected end of file: read 467 bytes instead of 900
  File "/usr/local/lib/python2.7/dist-packages/yandextank/core/consoleworker.py", line 375, in run
    self.core.plugins_configure()

  File "/usr/local/lib/python2.7/dist-packages/yandextank/core/tankcore.py", line 245, in plugins_configure
    plugin.configure()

  File "/usr/local/lib/python2.7/dist-packages/yandextank/plugins/Phantom/plugin.py", line 72, in configure
    self.phantom_config = self.phantom.config_file

  File "/usr/local/lib/python2.7/dist-packages/yandextank/plugins/Phantom/utils.py", line 106, in config_file
    self._config_file = self.compose_config()

  File "/usr/local/lib/python2.7/dist-packages/yandextank/plugins/Phantom/utils.py", line 114, in compose_config
    streams_config += stream.compose_config()

  File "/usr/local/lib/python2.7/dist-packages/yandextank/plugins/Phantom/utils.py", line 288, in compose_config
    self.stepper_wrapper.prepare_stepper()

  File "/usr/local/lib/python2.7/dist-packages/yandextank/stepper/main.py", line 228, in prepare_stepper
    self.__make_stpd_file()

  File "/usr/local/lib/python2.7/dist-packages/yandextank/stepper/main.py", line 318, in __make_stpd_file
    stepper.write(os)

  File "/usr/local/lib/python2.7/dist-packages/yandextank/stepper/main.py", line 61, in write
    for missile in self.ammo:

  File "/usr/local/lib/python2.7/dist-packages/yandextank/stepper/format.py", line 19, in <genexpr>
    "%s %s %s\n%s\n" % (len(missile), timestamp, marker, missile)

  File "/usr/local/lib/python2.7/dist-packages/yandextank/stepper/main.py", line 48, in <genexpr>
    return ((timestamp, marker or self.marker(missile), missile)

  File "/usr/local/lib/python2.7/dist-packages/yandextank/stepper/main.py", line 43, in <genexpr>
    ammo

  File "/usr/local/lib/python2.7/dist-packages/yandextank/stepper/main.py", line 44, in <genexpr>
    for ammo in ((missile, marker or self.marker(missile))

  File "/usr/local/lib/python2.7/dist-packages/yandextank/stepper/missile.py", line 139, in __iter__
    % (len(missile), chunk_size))

2021-09-16 12:39:26,523	Job number is not available yet
2021-09-16 12:39:26,526	Job number is not available yet
2021-09-16 12:39:26,534	File already exists: /var/loadtest/logs/2021-09-16_12-39-26.385089/phantom_vRqpc3.log
2021-09-16 12:39:26,537	File already exists: /var/loadtest/logs/2021-09-16_12-39-26.385089/phout_E8HdkI.log
2021-09-16 12:39:26,541	File not found to collect: validation_error.yaml
2021-09-16 12:39:26,542	File already exists: /var/loadtest/logs/2021-09-16_12-39-26.385089/phantom_stat_HnJuyO.log
2021-09-16 12:39:26,545	File already exists: /var/loadtest/logs/2021-09-16_12-39-26.385089/answ_KeAWRO.log
2021-09-16 12:39:43,507	Failed to install monitoring agent to 192.168.1.73
Traceback (most recent call last):
  File "/usr/local/lib/python2.7/dist-packages/yandextank/plugins/Telegraf/client.py", line 209, in install
    out, errors, err_code = self.ssh.execute(cmd)
  File "/usr/local/lib/python2.7/dist-packages/yandextank/common/util.py", line 72, in execute
    with self.connect() as client:
  File "/usr/local/lib/python2.7/dist-packages/yandextank/common/util.py", line 42, in connect
    timeout=self.timeout, )
  File "/usr/local/lib/python2.7/dist-packages/paramiko/client.py", line 362, in connect
    raise NoValidConnectionsError(errors)
NoValidConnectionsError: [Errno None] Unable to connect to port 22 on 192.168.1.73
2021-09-16 12:40:12,444	Job number is not available yet
2021-09-16 12:40:12,446	Job number is not available yet
2021-09-16 12:40:12,457	File already exists: /var/loadtest/logs/2021-09-16_12-39-38.069583/phantom_Ju0DBp.log
2021-09-16 12:40:12,461	File already exists: /var/loadtest/logs/2021-09-16_12-39-38.069583/monitoring_zqxIv7.xml
2021-09-16 12:40:12,465	File already exists: /var/loadtest/logs/2021-09-16_12-39-38.069583/phout_FLmblI.log
2021-09-16 12:40:12,468	File already exists: /var/loadtest/logs/2021-09-16_12-39-38.069583/phantom_stdout_stderr_Pkj9mr.log
2021-09-16 12:40:12,471	File already exists: /var/loadtest/logs/2021-09-16_12-39-38.069583/phantom_EjpVsh.conf
2021-09-16 12:40:12,477	File not found to collect: validation_error.yaml
2021-09-16 12:40:12,483	File already exists: /var/loadtest/logs/2021-09-16_12-39-38.069583/phantom_stat_FHacM0.log
2021-09-16 12:40:12,486	File already exists: /var/loadtest/logs/2021-09-16_12-39-38.069583/answ_shQM6T.log
2021-09-16 12:46:02,700	Failed to install monitoring agent to 192.168.1.73
Traceback (most recent call last):
  File "/usr/local/lib/python2.7/dist-packages/yandextank/plugins/Telegraf/client.py", line 209, in install
    out, errors, err_code = self.ssh.execute(cmd)
  File "/usr/local/lib/python2.7/dist-packages/yandextank/common/util.py", line 72, in execute
    with self.connect() as client:
  File "/usr/local/lib/python2.7/dist-packages/yandextank/common/util.py", line 42, in connect
    timeout=self.timeout, )
  File "/usr/local/lib/python2.7/dist-packages/paramiko/client.py", line 362, in connect
    raise NoValidConnectionsError(errors)
NoValidConnectionsError: [Errno None] Unable to connect to port 22 on 192.168.1.73
2021-09-16 12:46:29,597	Job number is not available yet
2021-09-16 12:46:29,598	Job number is not available yet
2021-09-16 12:46:29,606	File already exists: /var/loadtest/logs/2021-09-16_12-46-02.272911/phantom_XQGnB2.log
2021-09-16 12:46:29,614	File already exists: /var/loadtest/logs/2021-09-16_12-46-02.272911/answ_ML2WXX.log
2021-09-16 12:46:29,617	File already exists: /var/loadtest/logs/2021-09-16_12-46-02.272911/phantom_stdout_stderr_qR6YRR.log
2021-09-16 12:46:29,620	File already exists: /var/loadtest/logs/2021-09-16_12-46-02.272911/phout_yqjvrY.log
2021-09-16 12:46:29,622	File already exists: /var/loadtest/logs/2021-09-16_12-46-02.272911/monitoring_sIkW0T.xml
2021-09-16 12:46:29,626	File not found to collect: validation_error.yaml
2021-09-16 12:46:29,630	File already exists: /var/loadtest/logs/2021-09-16_12-46-02.272911/phantom_stat_hkg7Vz.log
2021-09-16 12:46:29,631	File already exists: /var/loadtest/logs/2021-09-16_12-46-02.272911/phantom_gqP5m7.conf
2021-09-16 13:09:07,148	Exception occurred:
<class 'yandextank.stepper.module_exceptions.AmmoFileError'>: Error while reading ammo file. Position: 1042, header: '                                                                                                                                                                                                                                                                                                                                                          4    �                 �            f���|   h                    <   0                1      Arbat      Moscow     RUS    Russia  	   testovich      test       uniq id   ', original exception: invalid literal for int() with base 10: ''
  File "/usr/local/lib/python2.7/dist-packages/yandextank/core/consoleworker.py", line 375, in run
    self.core.plugins_configure()

  File "/usr/local/lib/python2.7/dist-packages/yandextank/core/tankcore.py", line 245, in plugins_configure
    plugin.configure()

  File "/usr/local/lib/python2.7/dist-packages/yandextank/plugins/Phantom/plugin.py", line 72, in configure
    self.phantom_config = self.phantom.config_file

  File "/usr/local/lib/python2.7/dist-packages/yandextank/plugins/Phantom/utils.py", line 106, in config_file
    self._config_file = self.compose_config()

  File "/usr/local/lib/python2.7/dist-packages/yandextank/plugins/Phantom/utils.py", line 114, in compose_config
    streams_config += stream.compose_config()

  File "/usr/local/lib/python2.7/dist-packages/yandextank/plugins/Phantom/utils.py", line 288, in compose_config
    self.stepper_wrapper.prepare_stepper()

  File "/usr/local/lib/python2.7/dist-packages/yandextank/stepper/main.py", line 228, in prepare_stepper
    self.__make_stpd_file()

  File "/usr/local/lib/python2.7/dist-packages/yandextank/stepper/main.py", line 318, in __make_stpd_file
    stepper.write(os)

  File "/usr/local/lib/python2.7/dist-packages/yandextank/stepper/main.py", line 61, in write
    for missile in self.ammo:

  File "/usr/local/lib/python2.7/dist-packages/yandextank/stepper/format.py", line 19, in <genexpr>
    "%s %s %s\n%s\n" % (len(missile), timestamp, marker, missile)

  File "/usr/local/lib/python2.7/dist-packages/yandextank/stepper/main.py", line 48, in <genexpr>
    return ((timestamp, marker or self.marker(missile), missile)

  File "/usr/local/lib/python2.7/dist-packages/yandextank/stepper/main.py", line 43, in <genexpr>
    ammo

  File "/usr/local/lib/python2.7/dist-packages/yandextank/stepper/main.py", line 44, in <genexpr>
    for ammo in ((missile, marker or self.marker(missile))

  File "/usr/local/lib/python2.7/dist-packages/yandextank/stepper/missile.py", line 144, in __iter__
    % (ammo_file.tell(), chunk_header, e))

2021-09-16 13:09:07,158	Job number is not available yet
2021-09-16 13:09:07,161	Job number is not available yet
2021-09-16 13:09:07,171	File already exists: /var/loadtest/logs/2021-09-16_13-09-07.003810/phantom_stat_9ezxf7.log
2021-09-16 13:09:07,174	File already exists: /var/loadtest/logs/2021-09-16_13-09-07.003810/phantom_tqhX49.log
2021-09-16 13:09:07,178	File already exists: /var/loadtest/logs/2021-09-16_13-09-07.003810/answ_UF_V0m.log
2021-09-16 13:09:07,182	File not found to collect: validation_error.yaml
2021-09-16 13:09:07,184	File already exists: /var/loadtest/logs/2021-09-16_13-09-07.003810/phout_XeD8pF.log
2021-09-16 13:09:48,318	Exception occurred:
<class 'yandextank.stepper.module_exceptions.AmmoFileError'>: Error while reading ammo file. Position: 1043, header: '                                                                                                                                                                                                                                                                                                                                                           4    �                 �            f���|   h                    <   0                1      Arbat      Moscow     RUS    Russia  	   testovich      test       uniq id   ', original exception: invalid literal for int() with base 10: ''
  File "/usr/local/lib/python2.7/dist-packages/yandextank/core/consoleworker.py", line 375, in run
    self.core.plugins_configure()

  File "/usr/local/lib/python2.7/dist-packages/yandextank/core/tankcore.py", line 245, in plugins_configure
    plugin.configure()

  File "/usr/local/lib/python2.7/dist-packages/yandextank/plugins/Phantom/plugin.py", line 72, in configure
    self.phantom_config = self.phantom.config_file

  File "/usr/local/lib/python2.7/dist-packages/yandextank/plugins/Phantom/utils.py", line 106, in config_file
    self._config_file = self.compose_config()

  File "/usr/local/lib/python2.7/dist-packages/yandextank/plugins/Phantom/utils.py", line 114, in compose_config
    streams_config += stream.compose_config()

  File "/usr/local/lib/python2.7/dist-packages/yandextank/plugins/Phantom/utils.py", line 288, in compose_config
    self.stepper_wrapper.prepare_stepper()

  File "/usr/local/lib/python2.7/dist-packages/yandextank/stepper/main.py", line 228, in prepare_stepper
    self.__make_stpd_file()

  File "/usr/local/lib/python2.7/dist-packages/yandextank/stepper/main.py", line 318, in __make_stpd_file
    stepper.write(os)

  File "/usr/local/lib/python2.7/dist-packages/yandextank/stepper/main.py", line 61, in write
    for missile in self.ammo:

  File "/usr/local/lib/python2.7/dist-packages/yandextank/stepper/format.py", line 19, in <genexpr>
    "%s %s %s\n%s\n" % (len(missile), timestamp, marker, missile)

  File "/usr/local/lib/python2.7/dist-packages/yandextank/stepper/main.py", line 48, in <genexpr>
    return ((timestamp, marker or self.marker(missile), missile)

  File "/usr/local/lib/python2.7/dist-packages/yandextank/stepper/main.py", line 43, in <genexpr>
    ammo

  File "/usr/local/lib/python2.7/dist-packages/yandextank/stepper/main.py", line 44, in <genexpr>
    for ammo in ((missile, marker or self.marker(missile))

  File "/usr/local/lib/python2.7/dist-packages/yandextank/stepper/missile.py", line 144, in __iter__
    % (ammo_file.tell(), chunk_header, e))

2021-09-16 13:09:48,333	Job number is not available yet
2021-09-16 13:09:48,335	Job number is not available yet
2021-09-16 13:09:48,345	File already exists: /var/loadtest/logs/2021-09-16_13-09-48.186485/answ_wlwlCb.log
2021-09-16 13:09:48,348	File already exists: /var/loadtest/logs/2021-09-16_13-09-48.186485/phantom_Af5arD.log
2021-09-16 13:09:48,351	File not found to collect: validation_error.yaml
2021-09-16 13:09:48,355	File already exists: /var/loadtest/logs/2021-09-16_13-09-48.186485/phout_OQCndk.log
2021-09-16 13:09:48,358	File already exists: /var/loadtest/logs/2021-09-16_13-09-48.186485/phantom_stat_t4dWm3.log
2021-09-16 13:10:07,134	Exception occurred:
<class 'yandextank.stepper.module_exceptions.AmmoFileError'>: Unexpected end of file: read 1152 bytes instead of 1500
  File "/usr/local/lib/python2.7/dist-packages/yandextank/core/consoleworker.py", line 375, in run
    self.core.plugins_configure()

  File "/usr/local/lib/python2.7/dist-packages/yandextank/core/tankcore.py", line 245, in plugins_configure
    plugin.configure()

  File "/usr/local/lib/python2.7/dist-packages/yandextank/plugins/Phantom/plugin.py", line 72, in configure
    self.phantom_config = self.phantom.config_file

  File "/usr/local/lib/python2.7/dist-packages/yandextank/plugins/Phantom/utils.py", line 106, in config_file
    self._config_file = self.compose_config()

  File "/usr/local/lib/python2.7/dist-packages/yandextank/plugins/Phantom/utils.py", line 114, in compose_config
    streams_config += stream.compose_config()

  File "/usr/local/lib/python2.7/dist-packages/yandextank/plugins/Phantom/utils.py", line 288, in compose_config
    self.stepper_wrapper.prepare_stepper()

  File "/usr/local/lib/python2.7/dist-packages/yandextank/stepper/main.py", line 228, in prepare_stepper
    self.__make_stpd_file()

  File "/usr/local/lib/python2.7/dist-packages/yandextank/stepper/main.py", line 318, in __make_stpd_file
    stepper.write(os)

  File "/usr/local/lib/python2.7/dist-packages/yandextank/stepper/main.py", line 61, in write
    for missile in self.ammo:

  File "/usr/local/lib/python2.7/dist-packages/yandextank/stepper/format.py", line 19, in <genexpr>
    "%s %s %s\n%s\n" % (len(missile), timestamp, marker, missile)

  File "/usr/local/lib/python2.7/dist-packages/yandextank/stepper/main.py", line 48, in <genexpr>
    return ((timestamp, marker or self.marker(missile), missile)

  File "/usr/local/lib/python2.7/dist-packages/yandextank/stepper/main.py", line 43, in <genexpr>
    ammo

  File "/usr/local/lib/python2.7/dist-packages/yandextank/stepper/main.py", line 44, in <genexpr>
    for ammo in ((missile, marker or self.marker(missile))

  File "/usr/local/lib/python2.7/dist-packages/yandextank/stepper/missile.py", line 139, in __iter__
    % (len(missile), chunk_size))

2021-09-16 13:10:07,142	Job number is not available yet
2021-09-16 13:10:07,144	Job number is not available yet
2021-09-16 13:10:07,151	File already exists: /var/loadtest/logs/2021-09-16_13-10-07.017552/phout_d2LUKl.log
2021-09-16 13:10:07,154	File already exists: /var/loadtest/logs/2021-09-16_13-10-07.017552/answ_MyU_FW.log
2021-09-16 13:10:07,157	File not found to collect: validation_error.yaml
2021-09-16 13:10:07,159	File already exists: /var/loadtest/logs/2021-09-16_13-10-07.017552/phantom_stat_1blxwC.log
2021-09-16 13:10:07,162	File already exists: /var/loadtest/logs/2021-09-16_13-10-07.017552/phantom_8IW3HC.log
2021-09-16 13:10:15,828	Failed to install monitoring agent to 192.168.1.73
Traceback (most recent call last):
  File "/usr/local/lib/python2.7/dist-packages/yandextank/plugins/Telegraf/client.py", line 209, in install
    out, errors, err_code = self.ssh.execute(cmd)
  File "/usr/local/lib/python2.7/dist-packages/yandextank/common/util.py", line 72, in execute
    with self.connect() as client:
  File "/usr/local/lib/python2.7/dist-packages/yandextank/common/util.py", line 42, in connect
    timeout=self.timeout, )
  File "/usr/local/lib/python2.7/dist-packages/paramiko/client.py", line 362, in connect
    raise NoValidConnectionsError(errors)
NoValidConnectionsError: [Errno None] Unable to connect to port 22 on 192.168.1.73
2021-09-16 13:10:42,840	Job number is not available yet
2021-09-16 13:10:42,842	Job number is not available yet
2021-09-16 13:10:42,847	File already exists: /var/loadtest/logs/2021-09-16_13-10-15.443817/monitoring_U2L9RB.xml
2021-09-16 13:10:42,851	File already exists: /var/loadtest/logs/2021-09-16_13-10-15.443817/phantom_stat_O5PXoR.log
2021-09-16 13:10:42,853	File already exists: /var/loadtest/logs/2021-09-16_13-10-15.443817/phout_mX9Bp4.log
2021-09-16 13:10:42,855	File already exists: /var/loadtest/logs/2021-09-16_13-10-15.443817/phantom_stdout_stderr_hWLCYJ.log
2021-09-16 13:10:42,859	File already exists: /var/loadtest/logs/2021-09-16_13-10-15.443817/answ_UIZxOU.log
2021-09-16 13:10:42,863	File not found to collect: validation_error.yaml
2021-09-16 13:10:42,866	File already exists: /var/loadtest/logs/2021-09-16_13-10-15.443817/phantom_UE7DYZ.log
2021-09-16 13:10:42,868	File already exists: /var/loadtest/logs/2021-09-16_13-10-15.443817/phantom_IZmbHA.conf
2021-09-16 13:11:32,144	Exception occurred:
<class 'yandextank.stepper.module_exceptions.AmmoFileError'>: Unexpected end of file: read 467 bytes instead of 900
  File "/usr/local/lib/python2.7/dist-packages/yandextank/core/consoleworker.py", line 375, in run
    self.core.plugins_configure()

  File "/usr/local/lib/python2.7/dist-packages/yandextank/core/tankcore.py", line 245, in plugins_configure
    plugin.configure()

  File "/usr/local/lib/python2.7/dist-packages/yandextank/plugins/Phantom/plugin.py", line 72, in configure
    self.phantom_config = self.phantom.config_file

  File "/usr/local/lib/python2.7/dist-packages/yandextank/plugins/Phantom/utils.py", line 106, in config_file
    self._config_file = self.compose_config()

  File "/usr/local/lib/python2.7/dist-packages/yandextank/plugins/Phantom/utils.py", line 114, in compose_config
    streams_config += stream.compose_config()

  File "/usr/local/lib/python2.7/dist-packages/yandextank/plugins/Phantom/utils.py", line 288, in compose_config
    self.stepper_wrapper.prepare_stepper()

  File "/usr/local/lib/python2.7/dist-packages/yandextank/stepper/main.py", line 228, in prepare_stepper
    self.__make_stpd_file()

  File "/usr/local/lib/python2.7/dist-packages/yandextank/stepper/main.py", line 318, in __make_stpd_file
    stepper.write(os)

  File "/usr/local/lib/python2.7/dist-packages/yandextank/stepper/main.py", line 61, in write
    for missile in self.ammo:

  File "/usr/local/lib/python2.7/dist-packages/yandextank/stepper/format.py", line 19, in <genexpr>
    "%s %s %s\n%s\n" % (len(missile), timestamp, marker, missile)

  File "/usr/local/lib/python2.7/dist-packages/yandextank/stepper/main.py", line 48, in <genexpr>
    return ((timestamp, marker or self.marker(missile), missile)

  File "/usr/local/lib/python2.7/dist-packages/yandextank/stepper/main.py", line 43, in <genexpr>
    ammo

  File "/usr/local/lib/python2.7/dist-packages/yandextank/stepper/main.py", line 44, in <genexpr>
    for ammo in ((missile, marker or self.marker(missile))

  File "/usr/local/lib/python2.7/dist-packages/yandextank/stepper/missile.py", line 139, in __iter__
    % (len(missile), chunk_size))

2021-09-16 13:11:32,151	Job number is not available yet
2021-09-16 13:11:32,153	Job number is not available yet
2021-09-16 13:11:32,159	File already exists: /var/loadtest/logs/2021-09-16_13-11-32.008090/phout_isc0Uq.log
2021-09-16 13:11:32,161	File already exists: /var/loadtest/logs/2021-09-16_13-11-32.008090/phantom_kohnTp.log
2021-09-16 13:11:32,164	File not found to collect: validation_error.yaml
2021-09-16 13:11:32,166	File already exists: /var/loadtest/logs/2021-09-16_13-11-32.008090/answ_wUkVq4.log
2021-09-16 13:11:32,168	File already exists: /var/loadtest/logs/2021-09-16_13-11-32.008090/phantom_stat_CzIWN9.log
2021-09-16 13:11:39,099	Failed to install monitoring agent to 192.168.1.73
Traceback (most recent call last):
  File "/usr/local/lib/python2.7/dist-packages/yandextank/plugins/Telegraf/client.py", line 209, in install
    out, errors, err_code = self.ssh.execute(cmd)
  File "/usr/local/lib/python2.7/dist-packages/yandextank/common/util.py", line 72, in execute
    with self.connect() as client:
  File "/usr/local/lib/python2.7/dist-packages/yandextank/common/util.py", line 42, in connect
    timeout=self.timeout, )
  File "/usr/local/lib/python2.7/dist-packages/paramiko/client.py", line 362, in connect
    raise NoValidConnectionsError(errors)
NoValidConnectionsError: [Errno None] Unable to connect to port 22 on 192.168.1.73
2021-09-16 13:12:06,244	Job number is not available yet
2021-09-16 13:12:06,246	Job number is not available yet
2021-09-16 13:12:06,252	File already exists: /var/loadtest/logs/2021-09-16_13-11-38.660556/phantom_stat_eqh5i2.log
2021-09-16 13:12:06,255	File already exists: /var/loadtest/logs/2021-09-16_13-11-38.660556/phantom_S2bHFR.log
2021-09-16 13:12:06,257	File already exists: /var/loadtest/logs/2021-09-16_13-11-38.660556/phout_NlREvj.log
2021-09-16 13:12:06,259	File already exists: /var/loadtest/logs/2021-09-16_13-11-38.660556/monitoring_9IZRTW.xml
2021-09-16 13:12:06,261	File already exists: /var/loadtest/logs/2021-09-16_13-11-38.660556/phantom_stdout_stderr_9qRgyo.log
2021-09-16 13:12:06,264	File already exists: /var/loadtest/logs/2021-09-16_13-11-38.660556/answ_oL0wUO.log
2021-09-16 13:12:06,267	File not found to collect: validation_error.yaml
2021-09-16 13:12:06,268	File already exists: /var/loadtest/logs/2021-09-16_13-11-38.660556/phantom_PnWM6A.conf
2021-09-16 13:12:14,391	Failed to install monitoring agent to 192.168.1.73
Traceback (most recent call last):
  File "/usr/local/lib/python2.7/dist-packages/yandextank/plugins/Telegraf/client.py", line 209, in install
    out, errors, err_code = self.ssh.execute(cmd)
  File "/usr/local/lib/python2.7/dist-packages/yandextank/common/util.py", line 72, in execute
    with self.connect() as client:
  File "/usr/local/lib/python2.7/dist-packages/yandextank/common/util.py", line 42, in connect
    timeout=self.timeout, )
  File "/usr/local/lib/python2.7/dist-packages/paramiko/client.py", line 362, in connect
    raise NoValidConnectionsError(errors)
NoValidConnectionsError: [Errno None] Unable to connect to port 22 on 192.168.1.73
2021-09-16 13:12:52,366	Job number is not available yet
2021-09-16 13:12:52,368	Job number is not available yet
2021-09-16 13:12:52,378	File already exists: /var/loadtest/logs/2021-09-16_13-12-14.019873/phantom_stat_0eexTQ.log
2021-09-16 13:12:52,381	File already exists: /var/loadtest/logs/2021-09-16_13-12-14.019873/phantom_stdout_stderr_iqPxvh.log
2021-09-16 13:12:52,385	File already exists: /var/loadtest/logs/2021-09-16_13-12-14.019873/phantom_I0O2NN.log
2021-09-16 13:12:52,389	File already exists: /var/loadtest/logs/2021-09-16_13-12-14.019873/phout_h9KxTj.log
2021-09-16 13:12:52,394	File already exists: /var/loadtest/logs/2021-09-16_13-12-14.019873/phantom_bTHMfA.conf
2021-09-16 13:12:52,399	File not found to collect: validation_error.yaml
2021-09-16 13:12:52,405	File already exists: /var/loadtest/logs/2021-09-16_13-12-14.019873/monitoring_nPf4Wv.xml
2021-09-16 13:12:52,409	File already exists: /var/loadtest/logs/2021-09-16_13-12-14.019873/answ_KkbGyK.log
2021-09-16 13:18:22,264	Exception occurred:
<type 'exceptions.RuntimeError'>: All connection attempts failed for 192.168.1.73, use {phantom.connection_test: false} to disable it
  File "/usr/local/lib/python2.7/dist-packages/yandextank/core/consoleworker.py", line 375, in run
    self.core.plugins_configure()

  File "/usr/local/lib/python2.7/dist-packages/yandextank/core/tankcore.py", line 245, in plugins_configure
    plugin.configure()

  File "/usr/local/lib/python2.7/dist-packages/yandextank/plugins/Phantom/plugin.py", line 72, in configure
    self.phantom_config = self.phantom.config_file

  File "/usr/local/lib/python2.7/dist-packages/yandextank/plugins/Phantom/plugin.py", line 81, in phantom
    self._phantom.read_config()

  File "/usr/local/lib/python2.7/dist-packages/yandextank/plugins/Phantom/utils.py", line 95, in read_config
    stream.read_config()

  File "/usr/local/lib/python2.7/dist-packages/yandextank/plugins/Phantom/utils.py", line 275, in read_config
    self.address, do_test_connect, explicit_port)

  File "/usr/local/lib/python2.7/dist-packages/yandextank/common/util.py", line 555, in resolve
    raise RuntimeError(msg % address_str)

2021-09-16 13:18:22,272	Job number is not available yet
2021-09-16 13:18:22,273	Job number is not available yet
2021-09-16 13:18:22,281	File already exists: /var/loadtest/logs/2021-09-16_13-18-22.140184/phantom_stat_BOdlua.log
2021-09-16 13:18:22,284	File already exists: /var/loadtest/logs/2021-09-16_13-18-22.140184/phantom_H1szRI.log
2021-09-16 13:18:22,287	File not found to collect: validation_error.yaml
2021-09-16 13:18:22,289	File already exists: /var/loadtest/logs/2021-09-16_13-18-22.140184/phout__sJeLe.log
2021-09-16 13:18:22,291	File already exists: /var/loadtest/logs/2021-09-16_13-18-22.140184/answ_QWPvKk.log
2021-09-16 13:18:31,400	Failed to install monitoring agent to 192.168.1.73
Traceback (most recent call last):
  File "/usr/local/lib/python2.7/dist-packages/yandextank/plugins/Telegraf/client.py", line 209, in install
    out, errors, err_code = self.ssh.execute(cmd)
  File "/usr/local/lib/python2.7/dist-packages/yandextank/common/util.py", line 72, in execute
    with self.connect() as client:
  File "/usr/local/lib/python2.7/dist-packages/yandextank/common/util.py", line 42, in connect
    timeout=self.timeout, )
  File "/usr/local/lib/python2.7/dist-packages/paramiko/client.py", line 362, in connect
    raise NoValidConnectionsError(errors)
NoValidConnectionsError: [Errno None] Unable to connect to port 22 on 192.168.1.73
2021-09-16 13:18:31,631	Interrupting
2021-09-16 13:18:46,816	Job number is not available yet
2021-09-16 13:18:46,818	Job number is not available yet
2021-09-16 13:18:46,824	File already exists: /var/loadtest/logs/2021-09-16_13-18-30.997459/monitoring_w7Tf_Y.xml
2021-09-16 13:18:46,828	File already exists: /var/loadtest/logs/2021-09-16_13-18-30.997459/phantom_stat_9wiz1p.log
2021-09-16 13:18:46,831	File already exists: /var/loadtest/logs/2021-09-16_13-18-30.997459/phantom_Fssfyp.log
2021-09-16 13:18:46,834	File already exists: /var/loadtest/logs/2021-09-16_13-18-30.997459/answ_N2r2n8.log
2021-09-16 13:18:46,837	File not found to collect: validation_error.yaml
2021-09-16 13:18:46,839	File already exists: /var/loadtest/logs/2021-09-16_13-18-30.997459/phout_mp6ca4.log
2021-09-16 13:18:46,842	File already exists: /var/loadtest/logs/2021-09-16_13-18-30.997459/phantom_hOQrRd.conf
2021-09-16 13:18:54,987	Failed to install monitoring agent to 192.168.1.73
Traceback (most recent call last):
  File "/usr/local/lib/python2.7/dist-packages/yandextank/plugins/Telegraf/client.py", line 209, in install
    out, errors, err_code = self.ssh.execute(cmd)
  File "/usr/local/lib/python2.7/dist-packages/yandextank/common/util.py", line 72, in execute
    with self.connect() as client:
  File "/usr/local/lib/python2.7/dist-packages/yandextank/common/util.py", line 42, in connect
    timeout=self.timeout, )
  File "/usr/local/lib/python2.7/dist-packages/paramiko/client.py", line 362, in connect
    raise NoValidConnectionsError(errors)
NoValidConnectionsError: [Errno None] Unable to connect to port 22 on 192.168.1.73
2021-09-16 13:19:32,961	Job number is not available yet
2021-09-16 13:19:32,962	Job number is not available yet
2021-09-16 13:19:32,968	File already exists: /var/loadtest/logs/2021-09-16_13-18-54.598015/phantom_stat_TxWxmk.log
2021-09-16 13:19:32,970	File already exists: /var/loadtest/logs/2021-09-16_13-18-54.598015/phantom_stdout_stderr_gU5urB.log
2021-09-16 13:19:32,972	File already exists: /var/loadtest/logs/2021-09-16_13-18-54.598015/monitoring_gPj6oX.xml
2021-09-16 13:19:32,974	File already exists: /var/loadtest/logs/2021-09-16_13-18-54.598015/phantom_rJIYm_.log
2021-09-16 13:19:32,978	File already exists: /var/loadtest/logs/2021-09-16_13-18-54.598015/phout_FmXdYP.log
2021-09-16 13:19:32,982	File not found to collect: validation_error.yaml
2021-09-16 13:19:32,983	File already exists: /var/loadtest/logs/2021-09-16_13-18-54.598015/phantom_mzmlCO.conf
2021-09-16 13:19:32,986	File already exists: /var/loadtest/logs/2021-09-16_13-18-54.598015/answ_tqHxRd.log
2021-09-16 13:24:11,767	Exception occurred:
<type 'exceptions.RuntimeError'>: All connection attempts failed for 192.168.1.73, use {phantom.connection_test: false} to disable it
  File "/usr/local/lib/python2.7/dist-packages/yandextank/core/consoleworker.py", line 375, in run
    self.core.plugins_configure()

  File "/usr/local/lib/python2.7/dist-packages/yandextank/core/tankcore.py", line 245, in plugins_configure
    plugin.configure()

  File "/usr/local/lib/python2.7/dist-packages/yandextank/plugins/Phantom/plugin.py", line 72, in configure
    self.phantom_config = self.phantom.config_file

  File "/usr/local/lib/python2.7/dist-packages/yandextank/plugins/Phantom/plugin.py", line 81, in phantom
    self._phantom.read_config()

  File "/usr/local/lib/python2.7/dist-packages/yandextank/plugins/Phantom/utils.py", line 95, in read_config
    stream.read_config()

  File "/usr/local/lib/python2.7/dist-packages/yandextank/plugins/Phantom/utils.py", line 275, in read_config
    self.address, do_test_connect, explicit_port)

  File "/usr/local/lib/python2.7/dist-packages/yandextank/common/util.py", line 555, in resolve
    raise RuntimeError(msg % address_str)

2021-09-16 13:24:11,776	Job number is not available yet
2021-09-16 13:24:11,777	Job number is not available yet
2021-09-16 13:24:11,782	File already exists: /var/loadtest/logs/2021-09-16_13-24-11.672742/answ_KARN2n.log
2021-09-16 13:24:11,784	File not found to collect: validation_error.yaml
2021-09-16 13:24:11,786	File already exists: /var/loadtest/logs/2021-09-16_13-24-11.672742/phout_fHJmKa.log
2021-09-16 13:24:11,788	File already exists: /var/loadtest/logs/2021-09-16_13-24-11.672742/phantom_th1K7H.log
2021-09-16 13:24:11,790	File already exists: /var/loadtest/logs/2021-09-16_13-24-11.672742/phantom_stat_KT8kxP.log
2021-09-16 13:24:41,626	Exception occurred:
<class 'yandextank.stepper.module_exceptions.AmmoFileError'>: Unexpected end of file: read 705 bytes instead of 1000
  File "/usr/local/lib/python2.7/dist-packages/yandextank/core/consoleworker.py", line 375, in run
    self.core.plugins_configure()

  File "/usr/local/lib/python2.7/dist-packages/yandextank/core/tankcore.py", line 245, in plugins_configure
    plugin.configure()

  File "/usr/local/lib/python2.7/dist-packages/yandextank/plugins/Phantom/plugin.py", line 72, in configure
    self.phantom_config = self.phantom.config_file

  File "/usr/local/lib/python2.7/dist-packages/yandextank/plugins/Phantom/utils.py", line 106, in config_file
    self._config_file = self.compose_config()

  File "/usr/local/lib/python2.7/dist-packages/yandextank/plugins/Phantom/utils.py", line 114, in compose_config
    streams_config += stream.compose_config()

  File "/usr/local/lib/python2.7/dist-packages/yandextank/plugins/Phantom/utils.py", line 288, in compose_config
    self.stepper_wrapper.prepare_stepper()

  File "/usr/local/lib/python2.7/dist-packages/yandextank/stepper/main.py", line 228, in prepare_stepper
    self.__make_stpd_file()

  File "/usr/local/lib/python2.7/dist-packages/yandextank/stepper/main.py", line 318, in __make_stpd_file
    stepper.write(os)

  File "/usr/local/lib/python2.7/dist-packages/yandextank/stepper/main.py", line 61, in write
    for missile in self.ammo:

  File "/usr/local/lib/python2.7/dist-packages/yandextank/stepper/format.py", line 19, in <genexpr>
    "%s %s %s\n%s\n" % (len(missile), timestamp, marker, missile)

  File "/usr/local/lib/python2.7/dist-packages/yandextank/stepper/main.py", line 48, in <genexpr>
    return ((timestamp, marker or self.marker(missile), missile)

  File "/usr/local/lib/python2.7/dist-packages/yandextank/stepper/main.py", line 43, in <genexpr>
    ammo

  File "/usr/local/lib/python2.7/dist-packages/yandextank/stepper/main.py", line 44, in <genexpr>
    for ammo in ((missile, marker or self.marker(missile))

  File "/usr/local/lib/python2.7/dist-packages/yandextank/stepper/missile.py", line 139, in __iter__
    % (len(missile), chunk_size))

2021-09-16 13:24:41,633	Job number is not available yet
2021-09-16 13:24:41,635	Job number is not available yet
2021-09-16 13:24:41,642	File already exists: /var/loadtest/logs/2021-09-16_13-24-41.478108/phout_NNIGcJ.log
2021-09-16 13:24:41,644	File already exists: /var/loadtest/logs/2021-09-16_13-24-41.478108/answ_xpjl9q.log
2021-09-16 13:24:41,646	File already exists: /var/loadtest/logs/2021-09-16_13-24-41.478108/phantom_stat_Oi1lcA.log
2021-09-16 13:24:41,649	File not found to collect: validation_error.yaml
2021-09-16 13:24:41,651	File already exists: /var/loadtest/logs/2021-09-16_13-24-41.478108/phantom_uOHO6H.log
2021-09-16 13:24:50,141	Failed to install monitoring agent to 192.168.1.73
Traceback (most recent call last):
  File "/usr/local/lib/python2.7/dist-packages/yandextank/plugins/Telegraf/client.py", line 209, in install
    out, errors, err_code = self.ssh.execute(cmd)
  File "/usr/local/lib/python2.7/dist-packages/yandextank/common/util.py", line 72, in execute
    with self.connect() as client:
  File "/usr/local/lib/python2.7/dist-packages/yandextank/common/util.py", line 42, in connect
    timeout=self.timeout, )
  File "/usr/local/lib/python2.7/dist-packages/paramiko/client.py", line 362, in connect
    raise NoValidConnectionsError(errors)
NoValidConnectionsError: [Errno None] Unable to connect to port 22 on 192.168.1.73
2021-09-16 13:25:17,902	Job number is not available yet
2021-09-16 13:25:17,904	Job number is not available yet
2021-09-16 13:25:17,909	File already exists: /var/loadtest/logs/2021-09-16_13-24-49.698485/phantom_stat_97wfbA.log
2021-09-16 13:25:17,910	File already exists: /var/loadtest/logs/2021-09-16_13-24-49.698485/monitoring_MKWtfI.xml
2021-09-16 13:25:17,914	File already exists: /var/loadtest/logs/2021-09-16_13-24-49.698485/phout_HzGvkt.log
2021-09-16 13:25:17,916	File already exists: /var/loadtest/logs/2021-09-16_13-24-49.698485/phantom_stdout_stderr_OVknda.log
2021-09-16 13:25:17,918	File already exists: /var/loadtest/logs/2021-09-16_13-24-49.698485/phantom_eNXlEX.log
2021-09-16 13:25:17,920	File not found to collect: validation_error.yaml
2021-09-16 13:25:17,922	File already exists: /var/loadtest/logs/2021-09-16_13-24-49.698485/phantom_Jm939q.conf
2021-09-16 13:25:17,924	File already exists: /var/loadtest/logs/2021-09-16_13-24-49.698485/answ_3C27EH.log
2021-09-16 13:25:45,567	Failed to install monitoring agent to 192.168.1.73
Traceback (most recent call last):
  File "/usr/local/lib/python2.7/dist-packages/yandextank/plugins/Telegraf/client.py", line 209, in install
    out, errors, err_code = self.ssh.execute(cmd)
  File "/usr/local/lib/python2.7/dist-packages/yandextank/common/util.py", line 72, in execute
    with self.connect() as client:
  File "/usr/local/lib/python2.7/dist-packages/yandextank/common/util.py", line 42, in connect
    timeout=self.timeout, )
  File "/usr/local/lib/python2.7/dist-packages/paramiko/client.py", line 362, in connect
    raise NoValidConnectionsError(errors)
NoValidConnectionsError: [Errno None] Unable to connect to port 22 on 192.168.1.73
2021-09-16 13:26:12,578	Job number is not available yet
2021-09-16 13:26:12,580	Job number is not available yet
2021-09-16 13:26:12,586	File already exists: /var/loadtest/logs/2021-09-16_13-25-45.181365/phantom_stdout_stderr_sqixc4.log
2021-09-16 13:26:12,592	File already exists: /var/loadtest/logs/2021-09-16_13-25-45.181365/phantom_bLr9kM.log
2021-09-16 13:26:12,595	File already exists: /var/loadtest/logs/2021-09-16_13-25-45.181365/phantom_w2IB5f.conf
2021-09-16 13:26:12,598	File not found to collect: validation_error.yaml
2021-09-16 13:26:12,600	File already exists: /var/loadtest/logs/2021-09-16_13-25-45.181365/monitoring_0HVUI7.xml
2021-09-16 13:26:12,602	File already exists: /var/loadtest/logs/2021-09-16_13-25-45.181365/phout_b9nVoP.log
2021-09-16 13:26:12,605	File already exists: /var/loadtest/logs/2021-09-16_13-25-45.181365/phantom_stat_cZxpQY.log
2021-09-16 13:26:12,609	File already exists: /var/loadtest/logs/2021-09-16_13-25-45.181365/answ_B8KkOJ.log
2021-09-16 13:26:39,385	Failed to install monitoring agent to 192.168.1.73
Traceback (most recent call last):
  File "/usr/local/lib/python2.7/dist-packages/yandextank/plugins/Telegraf/client.py", line 209, in install
    out, errors, err_code = self.ssh.execute(cmd)
  File "/usr/local/lib/python2.7/dist-packages/yandextank/common/util.py", line 72, in execute
    with self.connect() as client:
  File "/usr/local/lib/python2.7/dist-packages/yandextank/common/util.py", line 42, in connect
    timeout=self.timeout, )
  File "/usr/local/lib/python2.7/dist-packages/paramiko/client.py", line 362, in connect
    raise NoValidConnectionsError(errors)
NoValidConnectionsError: [Errno None] Unable to connect to port 22 on 192.168.1.73
2021-09-16 13:27:17,291	Job number is not available yet
2021-09-16 13:27:17,293	Job number is not available yet
2021-09-16 13:27:17,298	File already exists: /var/loadtest/logs/2021-09-16_13-26-38.783479/phout_rLTeE6.log
2021-09-16 13:27:17,300	File already exists: /var/loadtest/logs/2021-09-16_13-26-38.783479/phantom_stdout_stderr_X5A0P4.log
2021-09-16 13:27:17,302	File already exists: /var/loadtest/logs/2021-09-16_13-26-38.783479/phantom_xf2Yy_.conf
2021-09-16 13:27:17,305	File not found to collect: validation_error.yaml
2021-09-16 13:27:17,308	File already exists: /var/loadtest/logs/2021-09-16_13-26-38.783479/monitoring_XfUSaz.xml
2021-09-16 13:27:17,310	File already exists: /var/loadtest/logs/2021-09-16_13-26-38.783479/phantom_stat_N__Cvm.log
2021-09-16 13:27:17,313	File already exists: /var/loadtest/logs/2021-09-16_13-26-38.783479/answ_06Owkf.log
2021-09-16 13:27:17,316	File already exists: /var/loadtest/logs/2021-09-16_13-26-38.783479/phantom_u0kgxw.log
2021-09-16 13:31:45,762	Exception occurred:
<class 'yandextank.stepper.module_exceptions.AmmoFileError'>: Unexpected end of file: read 467 bytes instead of 705
  File "/usr/local/lib/python2.7/dist-packages/yandextank/core/consoleworker.py", line 375, in run
    self.core.plugins_configure()

  File "/usr/local/lib/python2.7/dist-packages/yandextank/core/tankcore.py", line 245, in plugins_configure
    plugin.configure()

  File "/usr/local/lib/python2.7/dist-packages/yandextank/plugins/Phantom/plugin.py", line 72, in configure
    self.phantom_config = self.phantom.config_file

  File "/usr/local/lib/python2.7/dist-packages/yandextank/plugins/Phantom/utils.py", line 106, in config_file
    self._config_file = self.compose_config()

  File "/usr/local/lib/python2.7/dist-packages/yandextank/plugins/Phantom/utils.py", line 114, in compose_config
    streams_config += stream.compose_config()

  File "/usr/local/lib/python2.7/dist-packages/yandextank/plugins/Phantom/utils.py", line 288, in compose_config
    self.stepper_wrapper.prepare_stepper()

  File "/usr/local/lib/python2.7/dist-packages/yandextank/stepper/main.py", line 228, in prepare_stepper
    self.__make_stpd_file()

  File "/usr/local/lib/python2.7/dist-packages/yandextank/stepper/main.py", line 318, in __make_stpd_file
    stepper.write(os)

  File "/usr/local/lib/python2.7/dist-packages/yandextank/stepper/main.py", line 61, in write
    for missile in self.ammo:

  File "/usr/local/lib/python2.7/dist-packages/yandextank/stepper/format.py", line 19, in <genexpr>
    "%s %s %s\n%s\n" % (len(missile), timestamp, marker, missile)

  File "/usr/local/lib/python2.7/dist-packages/yandextank/stepper/main.py", line 48, in <genexpr>
    return ((timestamp, marker or self.marker(missile), missile)

  File "/usr/local/lib/python2.7/dist-packages/yandextank/stepper/main.py", line 43, in <genexpr>
    ammo

  File "/usr/local/lib/python2.7/dist-packages/yandextank/stepper/main.py", line 44, in <genexpr>
    for ammo in ((missile, marker or self.marker(missile))

  File "/usr/local/lib/python2.7/dist-packages/yandextank/stepper/missile.py", line 139, in __iter__
    % (len(missile), chunk_size))

2021-09-16 13:31:45,768	Job number is not available yet
2021-09-16 13:31:45,770	Job number is not available yet
2021-09-16 13:31:45,779	File already exists: /var/loadtest/logs/2021-09-16_13-31-45.640425/phout_verT2N.log
2021-09-16 13:31:45,781	File already exists: /var/loadtest/logs/2021-09-16_13-31-45.640425/phantom_qxXm4_.log
2021-09-16 13:31:45,783	File already exists: /var/loadtest/logs/2021-09-16_13-31-45.640425/phantom_stat_tr6ZKQ.log
2021-09-16 13:31:45,785	File not found to collect: validation_error.yaml
2021-09-16 13:31:45,787	File already exists: /var/loadtest/logs/2021-09-16_13-31-45.640425/answ_VvoPPv.log
2021-09-16 13:31:53,874	Failed to install monitoring agent to 192.168.1.73
Traceback (most recent call last):
  File "/usr/local/lib/python2.7/dist-packages/yandextank/plugins/Telegraf/client.py", line 209, in install
    out, errors, err_code = self.ssh.execute(cmd)
  File "/usr/local/lib/python2.7/dist-packages/yandextank/common/util.py", line 72, in execute
    with self.connect() as client:
  File "/usr/local/lib/python2.7/dist-packages/yandextank/common/util.py", line 42, in connect
    timeout=self.timeout, )
  File "/usr/local/lib/python2.7/dist-packages/paramiko/client.py", line 362, in connect
    raise NoValidConnectionsError(errors)
NoValidConnectionsError: [Errno None] Unable to connect to port 22 on 192.168.1.73
2021-09-16 13:32:31,852	Job number is not available yet
2021-09-16 13:32:31,854	Job number is not available yet
2021-09-16 13:32:31,860	File already exists: /var/loadtest/logs/2021-09-16_13-31-53.162456/phantom_qtUa7z.log
2021-09-16 13:32:31,862	File already exists: /var/loadtest/logs/2021-09-16_13-31-53.162456/monitoring_BpLLRr.xml
2021-09-16 13:32:31,864	File already exists: /var/loadtest/logs/2021-09-16_13-31-53.162456/phantom_stdout_stderr_1bFanw.log
2021-09-16 13:32:31,866	File already exists: /var/loadtest/logs/2021-09-16_13-31-53.162456/phout_wwPx9v.log
2021-09-16 13:32:31,869	File already exists: /var/loadtest/logs/2021-09-16_13-31-53.162456/phantom_stat_B4Z3RR.log
2021-09-16 13:32:31,872	File not found to collect: validation_error.yaml
2021-09-16 13:32:31,874	File already exists: /var/loadtest/logs/2021-09-16_13-31-53.162456/phantom_yvnU5D.conf
2021-09-16 13:32:31,876	File already exists: /var/loadtest/logs/2021-09-16_13-31-53.162456/answ_QPsriK.log
2021-09-16 13:34:29,875	Failed to install monitoring agent to 192.168.1.73
Traceback (most recent call last):
  File "/usr/local/lib/python2.7/dist-packages/yandextank/plugins/Telegraf/client.py", line 209, in install
    out, errors, err_code = self.ssh.execute(cmd)
  File "/usr/local/lib/python2.7/dist-packages/yandextank/common/util.py", line 72, in execute
    with self.connect() as client:
  File "/usr/local/lib/python2.7/dist-packages/yandextank/common/util.py", line 42, in connect
    timeout=self.timeout, )
  File "/usr/local/lib/python2.7/dist-packages/paramiko/client.py", line 362, in connect
    raise NoValidConnectionsError(errors)
NoValidConnectionsError: [Errno None] Unable to connect to port 22 on 192.168.1.73
2021-09-16 13:34:58,534	Job number is not available yet
2021-09-16 13:34:58,536	Job number is not available yet
2021-09-16 13:34:58,544	File already exists: /var/loadtest/logs/2021-09-16_13-34-29.482745/answ_NxPk24.log
2021-09-16 13:34:58,548	File already exists: /var/loadtest/logs/2021-09-16_13-34-29.482745/phantom_stat_yy_XT6.log
2021-09-16 13:34:58,551	File already exists: /var/loadtest/logs/2021-09-16_13-34-29.482745/phantom_lVsasg.log
2021-09-16 13:34:58,554	File already exists: /var/loadtest/logs/2021-09-16_13-34-29.482745/phout_yHb5AT.log
2021-09-16 13:34:58,557	File already exists: /var/loadtest/logs/2021-09-16_13-34-29.482745/phantom_stdout_stderr_eLUQrd.log
2021-09-16 13:34:58,561	File not found to collect: validation_error.yaml
2021-09-16 13:34:58,564	File already exists: /var/loadtest/logs/2021-09-16_13-34-29.482745/monitoring_muxHle.xml
2021-09-16 13:34:58,567	File already exists: /var/loadtest/logs/2021-09-16_13-34-29.482745/phantom_6YswIA.conf
2021-09-16 13:58:51,275	Exception occurred:
<class 'yandextank.stepper.module_exceptions.AmmoFileError'>: Unexpected end of file: read 466 bytes instead of 473
  File "/usr/local/lib/python2.7/dist-packages/yandextank/core/consoleworker.py", line 375, in run
    self.core.plugins_configure()

  File "/usr/local/lib/python2.7/dist-packages/yandextank/core/tankcore.py", line 245, in plugins_configure
    plugin.configure()

  File "/usr/local/lib/python2.7/dist-packages/yandextank/plugins/Phantom/plugin.py", line 72, in configure
    self.phantom_config = self.phantom.config_file

  File "/usr/local/lib/python2.7/dist-packages/yandextank/plugins/Phantom/utils.py", line 106, in config_file
    self._config_file = self.compose_config()

  File "/usr/local/lib/python2.7/dist-packages/yandextank/plugins/Phantom/utils.py", line 114, in compose_config
    streams_config += stream.compose_config()

  File "/usr/local/lib/python2.7/dist-packages/yandextank/plugins/Phantom/utils.py", line 288, in compose_config
    self.stepper_wrapper.prepare_stepper()

  File "/usr/local/lib/python2.7/dist-packages/yandextank/stepper/main.py", line 228, in prepare_stepper
    self.__make_stpd_file()

  File "/usr/local/lib/python2.7/dist-packages/yandextank/stepper/main.py", line 318, in __make_stpd_file
    stepper.write(os)

  File "/usr/local/lib/python2.7/dist-packages/yandextank/stepper/main.py", line 61, in write
    for missile in self.ammo:

  File "/usr/local/lib/python2.7/dist-packages/yandextank/stepper/format.py", line 19, in <genexpr>
    "%s %s %s\n%s\n" % (len(missile), timestamp, marker, missile)

  File "/usr/local/lib/python2.7/dist-packages/yandextank/stepper/main.py", line 48, in <genexpr>
    return ((timestamp, marker or self.marker(missile), missile)

  File "/usr/local/lib/python2.7/dist-packages/yandextank/stepper/main.py", line 43, in <genexpr>
    ammo

  File "/usr/local/lib/python2.7/dist-packages/yandextank/stepper/main.py", line 44, in <genexpr>
    for ammo in ((missile, marker or self.marker(missile))

  File "/usr/local/lib/python2.7/dist-packages/yandextank/stepper/missile.py", line 139, in __iter__
    % (len(missile), chunk_size))

2021-09-16 13:58:51,286	Job number is not available yet
2021-09-16 13:58:51,288	Job number is not available yet
2021-09-16 13:58:51,297	File already exists: /var/loadtest/logs/2021-09-16_13-58-51.156561/answ_KjtQcg.log
2021-09-16 13:58:51,301	File not found to collect: validation_error.yaml
2021-09-16 13:58:51,304	File already exists: /var/loadtest/logs/2021-09-16_13-58-51.156561/phantom_kCo7jt.log
2021-09-16 13:58:51,305	File already exists: /var/loadtest/logs/2021-09-16_13-58-51.156561/phantom_stat_TV2VTh.log
2021-09-16 13:58:51,307	File already exists: /var/loadtest/logs/2021-09-16_13-58-51.156561/phout_5zBvOc.log
2021-09-16 14:02:50,032	Exception occurred:
<class 'yandextank.stepper.module_exceptions.AmmoFileError'>: Error while reading ammo file. Position: 479, header: ' ', original exception: invalid literal for int() with base 10: ''
  File "/usr/local/lib/python2.7/dist-packages/yandextank/core/consoleworker.py", line 375, in run
    self.core.plugins_configure()

  File "/usr/local/lib/python2.7/dist-packages/yandextank/core/tankcore.py", line 245, in plugins_configure
    plugin.configure()

  File "/usr/local/lib/python2.7/dist-packages/yandextank/plugins/Phantom/plugin.py", line 72, in configure
    self.phantom_config = self.phantom.config_file

  File "/usr/local/lib/python2.7/dist-packages/yandextank/plugins/Phantom/utils.py", line 106, in config_file
    self._config_file = self.compose_config()

  File "/usr/local/lib/python2.7/dist-packages/yandextank/plugins/Phantom/utils.py", line 114, in compose_config
    streams_config += stream.compose_config()

  File "/usr/local/lib/python2.7/dist-packages/yandextank/plugins/Phantom/utils.py", line 288, in compose_config
    self.stepper_wrapper.prepare_stepper()

  File "/usr/local/lib/python2.7/dist-packages/yandextank/stepper/main.py", line 228, in prepare_stepper
    self.__make_stpd_file()

  File "/usr/local/lib/python2.7/dist-packages/yandextank/stepper/main.py", line 318, in __make_stpd_file
    stepper.write(os)

  File "/usr/local/lib/python2.7/dist-packages/yandextank/stepper/main.py", line 61, in write
    for missile in self.ammo:

  File "/usr/local/lib/python2.7/dist-packages/yandextank/stepper/format.py", line 19, in <genexpr>
    "%s %s %s\n%s\n" % (len(missile), timestamp, marker, missile)

  File "/usr/local/lib/python2.7/dist-packages/yandextank/stepper/main.py", line 48, in <genexpr>
    return ((timestamp, marker or self.marker(missile), missile)

  File "/usr/local/lib/python2.7/dist-packages/yandextank/stepper/main.py", line 43, in <genexpr>
    ammo

  File "/usr/local/lib/python2.7/dist-packages/yandextank/stepper/main.py", line 44, in <genexpr>
    for ammo in ((missile, marker or self.marker(missile))

  File "/usr/local/lib/python2.7/dist-packages/yandextank/stepper/missile.py", line 144, in __iter__
    % (ammo_file.tell(), chunk_header, e))

2021-09-16 14:02:50,041	Job number is not available yet
2021-09-16 14:02:50,043	Job number is not available yet
2021-09-16 14:02:50,052	File already exists: /var/loadtest/logs/2021-09-16_14-02-49.929271/phantom_stat_TvWvk_.log
2021-09-16 14:02:50,054	File already exists: /var/loadtest/logs/2021-09-16_14-02-49.929271/answ_djHO5R.log
2021-09-16 14:02:50,056	File already exists: /var/loadtest/logs/2021-09-16_14-02-49.929271/phout_LubVhT.log
2021-09-16 14:02:50,059	File not found to collect: validation_error.yaml
2021-09-16 14:02:50,062	File already exists: /var/loadtest/logs/2021-09-16_14-02-49.929271/phantom__VT_T6.log
2021-09-16 14:03:03,687	Exception occurred:
<class 'yandextank.stepper.module_exceptions.AmmoFileError'>: Error while reading ammo file. Position: 478, header: ' ', original exception: invalid literal for int() with base 10: ''
  File "/usr/local/lib/python2.7/dist-packages/yandextank/core/consoleworker.py", line 375, in run
    self.core.plugins_configure()

  File "/usr/local/lib/python2.7/dist-packages/yandextank/core/tankcore.py", line 245, in plugins_configure
    plugin.configure()

  File "/usr/local/lib/python2.7/dist-packages/yandextank/plugins/Phantom/plugin.py", line 72, in configure
    self.phantom_config = self.phantom.config_file

  File "/usr/local/lib/python2.7/dist-packages/yandextank/plugins/Phantom/utils.py", line 106, in config_file
    self._config_file = self.compose_config()

  File "/usr/local/lib/python2.7/dist-packages/yandextank/plugins/Phantom/utils.py", line 114, in compose_config
    streams_config += stream.compose_config()

  File "/usr/local/lib/python2.7/dist-packages/yandextank/plugins/Phantom/utils.py", line 288, in compose_config
    self.stepper_wrapper.prepare_stepper()

  File "/usr/local/lib/python2.7/dist-packages/yandextank/stepper/main.py", line 228, in prepare_stepper
    self.__make_stpd_file()

  File "/usr/local/lib/python2.7/dist-packages/yandextank/stepper/main.py", line 318, in __make_stpd_file
    stepper.write(os)

  File "/usr/local/lib/python2.7/dist-packages/yandextank/stepper/main.py", line 61, in write
    for missile in self.ammo:

  File "/usr/local/lib/python2.7/dist-packages/yandextank/stepper/format.py", line 19, in <genexpr>
    "%s %s %s\n%s\n" % (len(missile), timestamp, marker, missile)

  File "/usr/local/lib/python2.7/dist-packages/yandextank/stepper/main.py", line 48, in <genexpr>
    return ((timestamp, marker or self.marker(missile), missile)

  File "/usr/local/lib/python2.7/dist-packages/yandextank/stepper/main.py", line 43, in <genexpr>
    ammo

  File "/usr/local/lib/python2.7/dist-packages/yandextank/stepper/main.py", line 44, in <genexpr>
    for ammo in ((missile, marker or self.marker(missile))

  File "/usr/local/lib/python2.7/dist-packages/yandextank/stepper/missile.py", line 144, in __iter__
    % (ammo_file.tell(), chunk_header, e))

2021-09-16 14:03:03,701	Job number is not available yet
2021-09-16 14:03:03,704	Job number is not available yet
2021-09-16 14:03:03,717	File already exists: /var/loadtest/logs/2021-09-16_14-03-03.565323/phout_GoeJ9v.log
2021-09-16 14:03:03,720	File already exists: /var/loadtest/logs/2021-09-16_14-03-03.565323/phantom_stat_Gkz5HZ.log
2021-09-16 14:03:03,725	File not found to collect: validation_error.yaml
2021-09-16 14:03:03,731	File already exists: /var/loadtest/logs/2021-09-16_14-03-03.565323/answ_xP74h1.log
2021-09-16 14:03:03,734	File already exists: /var/loadtest/logs/2021-09-16_14-03-03.565323/phantom_WScTOy.log
2021-09-16 14:06:00,215	Failed to install monitoring agent to 192.168.1.73
Traceback (most recent call last):
  File "/usr/local/lib/python2.7/dist-packages/yandextank/plugins/Telegraf/client.py", line 209, in install
    out, errors, err_code = self.ssh.execute(cmd)
  File "/usr/local/lib/python2.7/dist-packages/yandextank/common/util.py", line 72, in execute
    with self.connect() as client:
  File "/usr/local/lib/python2.7/dist-packages/yandextank/common/util.py", line 42, in connect
    timeout=self.timeout, )
  File "/usr/local/lib/python2.7/dist-packages/paramiko/client.py", line 362, in connect
    raise NoValidConnectionsError(errors)
NoValidConnectionsError: [Errno None] Unable to connect to port 22 on 192.168.1.73
2021-09-16 14:06:27,257	Job number is not available yet
2021-09-16 14:06:27,258	Job number is not available yet
2021-09-16 14:06:27,264	File already exists: /var/loadtest/logs/2021-09-16_14-05-59.791456/phout_IfjBwF.log
2021-09-16 14:06:27,266	File already exists: /var/loadtest/logs/2021-09-16_14-05-59.791456/answ_DJdYYw.log
2021-09-16 14:06:27,268	File already exists: /var/loadtest/logs/2021-09-16_14-05-59.791456/monitoring_hamPpH.xml
2021-09-16 14:06:27,271	File already exists: /var/loadtest/logs/2021-09-16_14-05-59.791456/phantom_PXCBa6.log
2021-09-16 14:06:27,273	File already exists: /var/loadtest/logs/2021-09-16_14-05-59.791456/phantom_a0nC5S.conf
2021-09-16 14:06:27,275	File already exists: /var/loadtest/logs/2021-09-16_14-05-59.791456/phantom_stdout_stderr_gzXVCZ.log
2021-09-16 14:06:27,277	File not found to collect: validation_error.yaml
2021-09-16 14:06:27,280	File already exists: /var/loadtest/logs/2021-09-16_14-05-59.791456/phantom_stat_Q9jEUQ.log
2021-09-16 14:13:53,115	Failed to install monitoring agent to 192.168.1.73
Traceback (most recent call last):
  File "/usr/local/lib/python2.7/dist-packages/yandextank/plugins/Telegraf/client.py", line 209, in install
    out, errors, err_code = self.ssh.execute(cmd)
  File "/usr/local/lib/python2.7/dist-packages/yandextank/common/util.py", line 72, in execute
    with self.connect() as client:
  File "/usr/local/lib/python2.7/dist-packages/yandextank/common/util.py", line 42, in connect
    timeout=self.timeout, )
  File "/usr/local/lib/python2.7/dist-packages/paramiko/client.py", line 362, in connect
    raise NoValidConnectionsError(errors)
NoValidConnectionsError: [Errno None] Unable to connect to port 22 on 192.168.1.73
2021-09-16 14:14:20,154	Job number is not available yet
2021-09-16 14:14:20,157	Job number is not available yet
2021-09-16 14:14:20,166	File already exists: /var/loadtest/logs/2021-09-16_14-13-52.659431/answ_Te8Axe.log
2021-09-16 14:14:20,170	File already exists: /var/loadtest/logs/2021-09-16_14-13-52.659431/phantom_zggDyX.log
2021-09-16 14:14:20,174	File already exists: /var/loadtest/logs/2021-09-16_14-13-52.659431/phout_QyHAyN.log
2021-09-16 14:14:20,178	File not found to collect: validation_error.yaml
2021-09-16 14:14:20,180	File already exists: /var/loadtest/logs/2021-09-16_14-13-52.659431/phantom_stdout_stderr_HcfWXb.log
2021-09-16 14:14:20,182	File already exists: /var/loadtest/logs/2021-09-16_14-13-52.659431/monitoring_IPBFKu.xml
2021-09-16 14:14:20,184	File already exists: /var/loadtest/logs/2021-09-16_14-13-52.659431/phantom_BeA_GK.conf
2021-09-16 14:14:20,186	File already exists: /var/loadtest/logs/2021-09-16_14-13-52.659431/phantom_stat_mLfQJy.log
