2021-09-12 09:54:45,084	Failed to install monitoring agent to 192.168.1.74
Traceback (most recent call last):
  File "/usr/local/lib/python2.7/dist-packages/yandextank/plugins/Telegraf/client.py", line 209, in install
    out, errors, err_code = self.ssh.execute(cmd)
  File "/usr/local/lib/python2.7/dist-packages/yandextank/common/util.py", line 72, in execute
    with self.connect() as client:
  File "/usr/local/lib/python2.7/dist-packages/yandextank/common/util.py", line 42, in connect
    timeout=self.timeout, )
  File "/usr/local/lib/python2.7/dist-packages/paramiko/client.py", line 362, in connect
    raise NoValidConnectionsError(errors)
NoValidConnectionsError: [Errno None] Unable to connect to port 22 on 192.168.1.74
2021-09-12 09:55:34,110	Autostop criterion requested test stop: http(5xx,100%,30s)
2021-09-12 09:55:34,122	Autostop criterion requested test stop: 5xx codes count higher than 100.0% for 30s, since 1631440501
2021-09-12 09:55:35,845	Job number is not available yet
2021-09-12 09:55:35,846	Job number is not available yet
2021-09-12 09:55:35,853	File already exists: /var/loadtest/logs/2021-09-12_09-54-42.908298/answ_oNNNtt.log
2021-09-12 09:55:35,856	File already exists: /var/loadtest/logs/2021-09-12_09-54-42.908298/phantom_stdout_stderr_krgqdv.log
2021-09-12 09:55:35,860	File already exists: /var/loadtest/logs/2021-09-12_09-54-42.908298/phantom_7S6oLK.log
2021-09-12 09:55:35,864	File already exists: /var/loadtest/logs/2021-09-12_09-54-42.908298/autostop_report.txt
2021-09-12 09:55:35,867	File already exists: /var/loadtest/logs/2021-09-12_09-54-42.908298/phout_N_tIc1.log
2021-09-12 09:55:35,869	File already exists: /var/loadtest/logs/2021-09-12_09-54-42.908298/phantom_hPCJ0V.conf
2021-09-12 09:55:35,873	File not found to collect: validation_error.yaml
2021-09-12 09:55:35,877	File already exists: /var/loadtest/logs/2021-09-12_09-54-42.908298/phantom_stat_a7miPc.log
2021-09-12 09:55:35,880	File already exists: /var/loadtest/logs/2021-09-12_09-54-42.908298/monitoring_tfG0BZ.xml
2021-09-12 10:01:11,017	Failed to install monitoring agent to 192.168.1.74
Traceback (most recent call last):
  File "/usr/local/lib/python2.7/dist-packages/yandextank/plugins/Telegraf/client.py", line 209, in install
    out, errors, err_code = self.ssh.execute(cmd)
  File "/usr/local/lib/python2.7/dist-packages/yandextank/common/util.py", line 72, in execute
    with self.connect() as client:
  File "/usr/local/lib/python2.7/dist-packages/yandextank/common/util.py", line 42, in connect
    timeout=self.timeout, )
  File "/usr/local/lib/python2.7/dist-packages/paramiko/client.py", line 362, in connect
    raise NoValidConnectionsError(errors)
NoValidConnectionsError: [Errno None] Unable to connect to port 22 on 192.168.1.74
2021-09-12 10:01:19,672	Interrupting
2021-09-12 10:01:26,406	Job number is not available yet
2021-09-12 10:01:26,408	Job number is not available yet
2021-09-12 10:01:26,416	File already exists: /var/loadtest/logs/2021-09-12_10-01-10.561105/phout_joLrB6.log
2021-09-12 10:01:26,419	File already exists: /var/loadtest/logs/2021-09-12_10-01-10.561105/phantom_eJX7XH.conf
2021-09-12 10:01:26,421	File already exists: /var/loadtest/logs/2021-09-12_10-01-10.561105/answ_Fu_UIJ.log
2021-09-12 10:01:26,423	File not found to collect: validation_error.yaml
2021-09-12 10:01:26,425	File already exists: /var/loadtest/logs/2021-09-12_10-01-10.561105/phantom_KhuxRY.log
2021-09-12 10:01:26,428	File already exists: /var/loadtest/logs/2021-09-12_10-01-10.561105/monitoring_CvSVuI.xml
2021-09-12 10:01:26,431	File already exists: /var/loadtest/logs/2021-09-12_10-01-10.561105/phantom_stat_8n0AIQ.log
2021-09-12 10:01:27,265	Failed to install monitoring agent to 192.168.1.74
Traceback (most recent call last):
  File "/usr/local/lib/python2.7/dist-packages/yandextank/plugins/Telegraf/client.py", line 209, in install
    out, errors, err_code = self.ssh.execute(cmd)
  File "/usr/local/lib/python2.7/dist-packages/yandextank/common/util.py", line 72, in execute
    with self.connect() as client:
  File "/usr/local/lib/python2.7/dist-packages/yandextank/common/util.py", line 42, in connect
    timeout=self.timeout, )
  File "/usr/local/lib/python2.7/dist-packages/paramiko/client.py", line 362, in connect
    raise NoValidConnectionsError(errors)
NoValidConnectionsError: [Errno None] Unable to connect to port 22 on 192.168.1.74
2021-09-12 10:03:46,327	Job number is not available yet
2021-09-12 10:03:46,329	Job number is not available yet
2021-09-12 10:03:46,339	File already exists: /var/loadtest/logs/2021-09-12_10-01-26.857094/phantom_6P_Lx2.log
2021-09-12 10:03:46,341	File already exists: /var/loadtest/logs/2021-09-12_10-01-26.857094/monitoring_wxmF6A.xml
2021-09-12 10:03:46,344	File not found to collect: validation_error.yaml
2021-09-12 10:03:46,346	File already exists: /var/loadtest/logs/2021-09-12_10-01-26.857094/phantom_stat_C6rSHw.log
2021-09-12 10:03:46,351	File already exists: /var/loadtest/logs/2021-09-12_10-01-26.857094/answ_SjJbxy.log
2021-09-12 10:03:46,354	File already exists: /var/loadtest/logs/2021-09-12_10-01-26.857094/phantom_k7qbar.conf
2021-09-12 10:03:46,357	File already exists: /var/loadtest/logs/2021-09-12_10-01-26.857094/phout_VPb4yd.log
2021-09-12 10:03:46,358	File already exists: /var/loadtest/logs/2021-09-12_10-01-26.857094/phantom_stdout_stderr_1D9jHH.log
