2021-09-03 09:56:26,472 [INFO] root consoleworker.py:434	Log file created
2021-09-03 09:56:26,473 [INFO] root consoleworker.py:438	Logging handler <logging.FileHandler object at 0x7fa4614c1c10> added
2021-09-03 09:56:26,474 [INFO] root consoleworker.py:438	Logging handler <logging.StreamHandler object at 0x7fa461509850> added
2021-09-03 09:56:26,475 [INFO] root consoleworker.py:438	Logging handler <logging.StreamHandler object at 0x7fa4614ada50> added
2021-09-03 09:56:26,476 [INFO] root consoleworker.py:373	Created a folder for the test. /var/loadtest/logs/2021-09-03_09-56-26.431447
2021-09-03 09:56:26,477 [INFO] yandextank.core.tankcore tankcore.py:237	Configuring plugins...
2021-09-03 09:56:26,478 [INFO] yandextank.core.tankcore tankcore.py:190	Loading plugins...
2021-09-03 09:56:26,479 [DEBUG] yandextank.core.tankcore tankcore.py:192	Loading plugin phantom from yandextank.plugins.Phantom
2021-09-03 09:56:26,480 [DEBUG] yandextank.core.tankcore tankcore.py:192	Loading plugin telegraf from yandextank.plugins.Telegraf
2021-09-03 09:56:26,482 [DEBUG] yandextank.core.tankcore tankcore.py:192	Loading plugin rcheck from yandextank.plugins.ResourceCheck
2021-09-03 09:56:26,483 [DEBUG] yandextank.core.tankcore tankcore.py:192	Loading plugin json_report from yandextank.plugins.JsonReport
2021-09-03 09:56:26,487 [DEBUG] yandextank.core.tankcore tankcore.py:192	Loading plugin rcassert from yandextank.plugins.RCAssert
2021-09-03 09:56:26,488 [DEBUG] yandextank.core.tankcore tankcore.py:192	Loading plugin console from yandextank.plugins.Console
2021-09-03 09:56:26,489 [DEBUG] yandextank.core.tankcore tankcore.py:192	Loading plugin shellexec from yandextank.plugins.ShellExec
2021-09-03 09:56:26,489 [DEBUG] yandextank.core.tankcore tankcore.py:192	Loading plugin autostop from yandextank.plugins.Autostop
2021-09-03 09:56:26,490 [DEBUG] yandextank.core.tankcore tankcore.py:212	Plugin instances: {'plugin_phantom': <yandextank.plugins.Phantom.plugin.Plugin object at 0x7fa461178610>, 'plugin_autostop': <yandextank.plugins.Autostop.plugin.Plugin object at 0x7fa461178f50>, 'plugin_shellexec': <yandextank.plugins.ShellExec.plugin.Plugin object at 0x7fa461178d90>, 'plugin_console': <yandextank.plugins.Console.plugin.Plugin object at 0x7fa461178cd0>, 'plugin_rcassert': <yandextank.plugins.RCAssert.plugin.Plugin object at 0x7fa461178b10>, 'plugin_telegraf': <yandextank.plugins.Telegraf.plugin.Plugin object at 0x7fa461178590>, 'plugin_rcheck': <yandextank.plugins.ResourceCheck.plugin.Plugin object at 0x7fa461178190>, 'plugin_json_report': <yandextank.plugins.JsonReport.plugin.Plugin object at 0x7fa461178310>}
2021-09-03 09:56:26,491 [DEBUG] yandextank.core.tankcore tankcore.py:244	Configuring <yandextank.plugins.Phantom.plugin.Plugin object at 0x7fa461178610>
2021-09-03 09:56:26,492 [DEBUG] yandextank.core.tankcore tankcore.py:391	Searching for plugin: <class 'yandextank.plugins.Autostop.plugin.Plugin'>
2021-09-03 09:56:26,500 [DEBUG] yandextank.core.tankcore tankcore.py:446	Adding artifact file to collect (keep=False): /var/loadtest/logs/2021-09-03_09-56-26.431447/answ_wNEDa2.log
2021-09-03 09:56:26,504 [DEBUG] yandextank.core.tankcore tankcore.py:446	Adding artifact file to collect (keep=False): /var/loadtest/logs/2021-09-03_09-56-26.431447/phout_9i1xVO.log
2021-09-03 09:56:26,504 [DEBUG] yandextank.core.tankcore tankcore.py:446	Adding artifact file to collect (keep=False): /var/loadtest/logs/2021-09-03_09-56-26.431447/phantom_stat_80dEH1.log
2021-09-03 09:56:26,507 [DEBUG] yandextank.core.tankcore tankcore.py:446	Adding artifact file to collect (keep=False): /var/loadtest/logs/2021-09-03_09-56-26.431447/phantom_Tvpxkp.log
2021-09-03 09:56:26,508 [DEBUG] yandextank.common.util util.py:479	Trying to resolve address string: localhost:9999
2021-09-03 09:56:26,509 [DEBUG] yandextank.common.util util.py:516	Parsing port
2021-09-03 09:56:26,511 [DEBUG] yandextank.common.util util.py:527	Lookup result: [(10, 1, 6, '', ('::1', 9999, 0, 0)), (10, 2, 17, '', ('::1', 9999, 0, 0)), (10, 3, 0, '', ('::1', 9999, 0, 0)), (2, 1, 6, '', ('127.0.0.1', 9999)), (2, 2, 17, '', ('127.0.0.1', 9999)), (2, 3, 0, '', ('127.0.0.1', 9999))]
2021-09-03 09:56:26,514 [INFO] yandextank.common.util util.py:546	Testing connection to resolved address ::1 and port 9999
2021-09-03 09:56:26,516 [DEBUG] yandextank.common.util util.py:565	Exception on connect attempt [::1]:9999 : Traceback (most recent call last):
  File "/usr/local/lib/python2.7/dist-packages/yandextank/common/util.py", line 561, in __test
    test_sock.connect(sa)
  File "/usr/lib/python2.7/socket.py", line 228, in meth
    return getattr(self._sock,name)(*args)
error: [Errno 111] Connection refused

2021-09-03 09:56:26,517 [INFO] yandextank.common.util util.py:549	Failed TCP connection test using [::1]:9999
2021-09-03 09:56:26,518 [DEBUG] yandextank.common.util util.py:550	Failed TCP connection test using [::1]:9999
Traceback (most recent call last):
  File "/usr/local/lib/python2.7/dist-packages/yandextank/common/util.py", line 547, in resolve
    self.__test(family, (parsed_ip, port))
  File "/usr/local/lib/python2.7/dist-packages/yandextank/common/util.py", line 567, in __test
    raise RuntimeError(msg % (sa[0], sa[1]))
RuntimeError: TCP Connection test failed for [::1]:9999, use phantom.connection_test=0 to disable it
2021-09-03 09:56:26,519 [INFO] yandextank.common.util util.py:546	Testing connection to resolved address ::1 and port 9999
2021-09-03 09:56:26,521 [DEBUG] yandextank.common.util util.py:565	Exception on connect attempt [::1]:9999 : Traceback (most recent call last):
  File "/usr/local/lib/python2.7/dist-packages/yandextank/common/util.py", line 561, in __test
    test_sock.connect(sa)
  File "/usr/lib/python2.7/socket.py", line 228, in meth
    return getattr(self._sock,name)(*args)
error: [Errno 111] Connection refused

2021-09-03 09:56:26,522 [INFO] yandextank.common.util util.py:549	Failed TCP connection test using [::1]:9999
2021-09-03 09:56:26,523 [DEBUG] yandextank.common.util util.py:550	Failed TCP connection test using [::1]:9999
Traceback (most recent call last):
  File "/usr/local/lib/python2.7/dist-packages/yandextank/common/util.py", line 547, in resolve
    self.__test(family, (parsed_ip, port))
  File "/usr/local/lib/python2.7/dist-packages/yandextank/common/util.py", line 567, in __test
    raise RuntimeError(msg % (sa[0], sa[1]))
RuntimeError: TCP Connection test failed for [::1]:9999, use phantom.connection_test=0 to disable it
2021-09-03 09:56:26,524 [INFO] yandextank.common.util util.py:546	Testing connection to resolved address ::1 and port 9999
2021-09-03 09:56:26,525 [DEBUG] yandextank.common.util util.py:565	Exception on connect attempt [::1]:9999 : Traceback (most recent call last):
  File "/usr/local/lib/python2.7/dist-packages/yandextank/common/util.py", line 561, in __test
    test_sock.connect(sa)
  File "/usr/lib/python2.7/socket.py", line 228, in meth
    return getattr(self._sock,name)(*args)
error: [Errno 111] Connection refused

2021-09-03 09:56:26,527 [INFO] yandextank.common.util util.py:549	Failed TCP connection test using [::1]:9999
2021-09-03 09:56:26,528 [DEBUG] yandextank.common.util util.py:550	Failed TCP connection test using [::1]:9999
Traceback (most recent call last):
  File "/usr/local/lib/python2.7/dist-packages/yandextank/common/util.py", line 547, in resolve
    self.__test(family, (parsed_ip, port))
  File "/usr/local/lib/python2.7/dist-packages/yandextank/common/util.py", line 567, in __test
    raise RuntimeError(msg % (sa[0], sa[1]))
RuntimeError: TCP Connection test failed for [::1]:9999, use phantom.connection_test=0 to disable it
2021-09-03 09:56:26,529 [INFO] yandextank.common.util util.py:546	Testing connection to resolved address 127.0.0.1 and port 9999
2021-09-03 09:56:26,530 [DEBUG] yandextank.common.util util.py:565	Exception on connect attempt [127.0.0.1]:9999 : Traceback (most recent call last):
  File "/usr/local/lib/python2.7/dist-packages/yandextank/common/util.py", line 561, in __test
    test_sock.connect(sa)
  File "/usr/lib/python2.7/socket.py", line 228, in meth
    return getattr(self._sock,name)(*args)
error: [Errno 111] Connection refused

2021-09-03 09:56:26,531 [INFO] yandextank.common.util util.py:549	Failed TCP connection test using [127.0.0.1]:9999
2021-09-03 09:56:26,531 [DEBUG] yandextank.common.util util.py:550	Failed TCP connection test using [127.0.0.1]:9999
Traceback (most recent call last):
  File "/usr/local/lib/python2.7/dist-packages/yandextank/common/util.py", line 547, in resolve
    self.__test(family, (parsed_ip, port))
  File "/usr/local/lib/python2.7/dist-packages/yandextank/common/util.py", line 567, in __test
    raise RuntimeError(msg % (sa[0], sa[1]))
RuntimeError: TCP Connection test failed for [127.0.0.1]:9999, use phantom.connection_test=0 to disable it
2021-09-03 09:56:26,532 [INFO] yandextank.common.util util.py:546	Testing connection to resolved address 127.0.0.1 and port 9999
2021-09-03 09:56:26,533 [DEBUG] yandextank.common.util util.py:565	Exception on connect attempt [127.0.0.1]:9999 : Traceback (most recent call last):
  File "/usr/local/lib/python2.7/dist-packages/yandextank/common/util.py", line 561, in __test
    test_sock.connect(sa)
  File "/usr/lib/python2.7/socket.py", line 228, in meth
    return getattr(self._sock,name)(*args)
error: [Errno 111] Connection refused

2021-09-03 09:56:26,534 [INFO] yandextank.common.util util.py:549	Failed TCP connection test using [127.0.0.1]:9999
2021-09-03 09:56:26,534 [DEBUG] yandextank.common.util util.py:550	Failed TCP connection test using [127.0.0.1]:9999
Traceback (most recent call last):
  File "/usr/local/lib/python2.7/dist-packages/yandextank/common/util.py", line 547, in resolve
    self.__test(family, (parsed_ip, port))
  File "/usr/local/lib/python2.7/dist-packages/yandextank/common/util.py", line 567, in __test
    raise RuntimeError(msg % (sa[0], sa[1]))
RuntimeError: TCP Connection test failed for [127.0.0.1]:9999, use phantom.connection_test=0 to disable it
2021-09-03 09:56:26,535 [INFO] yandextank.common.util util.py:546	Testing connection to resolved address 127.0.0.1 and port 9999
2021-09-03 09:56:26,536 [DEBUG] yandextank.common.util util.py:565	Exception on connect attempt [127.0.0.1]:9999 : Traceback (most recent call last):
  File "/usr/local/lib/python2.7/dist-packages/yandextank/common/util.py", line 561, in __test
    test_sock.connect(sa)
  File "/usr/lib/python2.7/socket.py", line 228, in meth
    return getattr(self._sock,name)(*args)
error: [Errno 111] Connection refused

2021-09-03 09:56:26,536 [INFO] yandextank.common.util util.py:549	Failed TCP connection test using [127.0.0.1]:9999
2021-09-03 09:56:26,537 [DEBUG] yandextank.common.util util.py:550	Failed TCP connection test using [127.0.0.1]:9999
Traceback (most recent call last):
  File "/usr/local/lib/python2.7/dist-packages/yandextank/common/util.py", line 547, in resolve
    self.__test(family, (parsed_ip, port))
  File "/usr/local/lib/python2.7/dist-packages/yandextank/common/util.py", line 567, in __test
    raise RuntimeError(msg % (sa[0], sa[1]))
RuntimeError: TCP Connection test failed for [127.0.0.1]:9999, use phantom.connection_test=0 to disable it
2021-09-03 09:56:26,538 [ERROR] root consoleworker.py:268	Exception occurred:
<type 'exceptions.RuntimeError'>: All connection attempts failed for localhost, use {phantom.connection_test: false} to disable it
  File "/usr/local/lib/python2.7/dist-packages/yandextank/core/consoleworker.py", line 375, in run
    self.core.plugins_configure()

  File "/usr/local/lib/python2.7/dist-packages/yandextank/core/tankcore.py", line 245, in plugins_configure
    plugin.configure()

  File "/usr/local/lib/python2.7/dist-packages/yandextank/plugins/Phantom/plugin.py", line 72, in configure
    self.phantom_config = self.phantom.config_file

  File "/usr/local/lib/python2.7/dist-packages/yandextank/plugins/Phantom/plugin.py", line 81, in phantom
    self._phantom.read_config()

  File "/usr/local/lib/python2.7/dist-packages/yandextank/plugins/Phantom/utils.py", line 95, in read_config
    stream.read_config()

  File "/usr/local/lib/python2.7/dist-packages/yandextank/plugins/Phantom/utils.py", line 275, in read_config
    self.address, do_test_connect, explicit_port)

  File "/usr/local/lib/python2.7/dist-packages/yandextank/common/util.py", line 555, in resolve
    raise RuntimeError(msg % address_str)

2021-09-03 09:56:26,540 [INFO] root consoleworker.py:269	Trying to clean up
2021-09-03 09:56:26,540 [INFO] yandextank.core.tankcore tankcore.py:561	Releasing lock: /var/lock/lunapark_Ke89nB.lock
2021-09-03 09:56:26,544 [WARNING] root consoleworker.py:408	Job number is not available yet
2021-09-03 09:56:26,545 [WARNING] root consoleworker.py:415	Job number is not available yet
2021-09-03 09:56:26,549 [DEBUG] yandextank.core.tankcore tankcore.py:367	Collecting artifacts
2021-09-03 09:56:26,549 [INFO] yandextank.core.tankcore tankcore.py:368	Artifacts dir: /var/loadtest/logs/2021-09-03_09-56-26.431447
2021-09-03 09:56:26,550 [DEBUG] yandextank.core.tankcore tankcore.py:422	Collecting file: /var/loadtest/logs/2021-09-03_09-56-26.431447/answ_wNEDa2.log to /var/loadtest/logs/2021-09-03_09-56-26.431447/answ_wNEDa2.log
2021-09-03 09:56:26,551 [WARNING] yandextank.core.tankcore tankcore.py:429	File already exists: /var/loadtest/logs/2021-09-03_09-56-26.431447/answ_wNEDa2.log
2021-09-03 09:56:26,552 [DEBUG] yandextank.core.tankcore tankcore.py:422	Collecting file: /var/loadtest/logs/2021-09-03_09-56-26.431447/phantom_stat_80dEH1.log to /var/loadtest/logs/2021-09-03_09-56-26.431447/phantom_stat_80dEH1.log
2021-09-03 09:56:26,553 [WARNING] yandextank.core.tankcore tankcore.py:429	File already exists: /var/loadtest/logs/2021-09-03_09-56-26.431447/phantom_stat_80dEH1.log
2021-09-03 09:56:26,554 [DEBUG] yandextank.core.tankcore tankcore.py:422	Collecting file: /var/loadtest/logs/2021-09-03_09-56-26.431447/phantom_Tvpxkp.log to /var/loadtest/logs/2021-09-03_09-56-26.431447/phantom_Tvpxkp.log
2021-09-03 09:56:26,554 [WARNING] yandextank.core.tankcore tankcore.py:429	File already exists: /var/loadtest/logs/2021-09-03_09-56-26.431447/phantom_Tvpxkp.log
2021-09-03 09:56:26,555 [DEBUG] yandextank.core.tankcore tankcore.py:422	Collecting file: /var/loadtest/logs/2021-09-03_09-56-26.431447/phout_9i1xVO.log to /var/loadtest/logs/2021-09-03_09-56-26.431447/phout_9i1xVO.log
2021-09-03 09:56:26,556 [WARNING] yandextank.core.tankcore tankcore.py:429	File already exists: /var/loadtest/logs/2021-09-03_09-56-26.431447/phout_9i1xVO.log
2021-09-03 09:56:26,558 [DEBUG] yandextank.core.tankcore tankcore.py:422	Collecting file: validation_error.yaml to /var/loadtest/logs/2021-09-03_09-56-26.431447/validation_error.yaml
2021-09-03 09:56:26,559 [WARNING] yandextank.core.tankcore tankcore.py:424	File not found to collect: validation_error.yaml
